Workbook
Name _C65800: #REF!
Name _C658000: #REF!
Name _C66000: #REF!
Name _C67000: #REF!
Name _C68000: #REF!

Sheet wells group 
B2: =[1]SIT!AQ2 -> WELLS No. | C2: =[1]SIT!AR2 -> REP. G.RATE M3/D | D2: =[1]SIT!AS2 -> REP. W.C % VOL | E2: =[1]SIT!AT2 -> REP. NET M3/D | F2: =[1]SIT!AU2 -> TEST G.RATE M3/D | G2: =[1]SIT!AV2 -> ACT. W.C % VOL | H2: =[1]SIT!AW2 -> ACT. NET M3/D | I2: =[1]SIT!AX2 -> DIFF. M3 NET | J2: PLATF.
A3: 1 | B3: =[1]SIT!AQ3 -> 113M-01 | C3: =[1]SIT!AR3 -> 75 | D3: =[1]SIT!AS3 -> 66 | E3: =[1]SIT!AT3 -> 25.5 | F3: =[1]SIT!AU3 -> 85 | G3: =[1]SIT!AV3 -> 68.6 | H3: =[1]SIT!AW3 -> 26.69 | I3: =[1]SIT!AX3 -> 1.19 | J3: 113M-1
A4: 2 | B4: =[1]SIT!AQ32 -> 113M-77 H | C4: =[1]SIT!AR32 -> 170 | D4: =[1]SIT!AS32 -> 85 | E4: =[1]SIT!AT32 -> 25.5 | F4: =[1]SIT!AU32 -> 170 | G4: =[1]SIT!AV32 -> 85.4 | H4: =[1]SIT!AW32 -> 24.82 | I4: =[1]SIT!AX32 -> -0.68
A5: 3 | B5: =[1]SIT!AZ11 -> 113M-94 | C5: =[1]SIT!BA11 -> 60 | D5: =[1]SIT!BB11 -> 80 | E5: =[1]SIT!BC11 -> 12 | F5: =[1]SIT!BD11 -> 60 | G5: =[1]SIT!BE11 -> 76.7 | H5: =[1]SIT!BF11 -> 13.98 | I5: =[1]SIT!BG11 -> 1.98
B6: 113M-120 | C6: =[1]SIT!BA31 -> 200 | D6: =[1]SIT!BB31 -> 27.8 | E6: =[1]SIT!BC31 -> 144.4 | F6: =[1]SIT!BD31 -> 200 | G6: =[1]SIT!BE31 -> 4.8 | H6: =[1]SIT!BF31 -> 190.4 | I6: =[1]SIT!BG31 -> 46
B7: TOTAL | C7: =SUM(C3:C6) -> 505 | E7: =SUM(E3:E6) -> 207.4 | F7: =SUM(F3:F6) -> 515 | H7: =SUM(H3:H6) -> 255.89 | I7: =SUM(I3:I6) -> 48.49
A8: 4 | B8: =[1]SIT!AQ4 -> 113M-02 | C8: =[1]SIT!AR4 -> 80 | D8: =[1]SIT!AS4 -> 79.6 | E8: =[1]SIT!AT4 -> 16.32 | F8: =[1]SIT!AU4 -> 80 | G8: =[1]SIT!AV4 -> 0.8 | H8: =[1]SIT!AW4 -> 79.36 | I8: =[1]SIT!AX4 -> 63.04 | J8: 113M-2
A9: 5 | B9: =[1]SIT!AQ15 -> 113M-46 | C9: =[1]SIT!AR15 -> 200 | D9: =[1]SIT!AS15 -> 95 | E9: =[1]SIT!AT15 -> 10 | F9: =[1]SIT!AU15 -> 185 | G9: =[1]SIT!AV15 -> 93.3 | H9: =[1]SIT!AW15 -> 12.395 | I9: =[1]SIT!AX15 -> 2.395
A10: 6 | B10: =[1]SIT!AQ25 -> *113M-67 | C10: =[1]SIT!AR25 -> 0 | D10: =[1]SIT!AS25 -> 97 | E10: =[1]SIT!AT25 -> 0 | F10: =[1]SIT!AU25 -> 0 | G10: =[1]SIT!AV25 -> 92.7 | H10: =[1]SIT!AW25 -> 0 | I10: =[1]SIT!AX25 -> 0
A11: 7 | B11: =[1]SIT!AZ7 -> 113M-84 | C11: =[1]SIT!BA7 -> 550 | D11: =[1]SIT!BB7 -> 27 | E11: =[1]SIT!BC7 -> 401.5 | F11: =[1]SIT!BD7 -> 545 | G11: =[1]SIT!BE7 -> 96 | H11: =[1]SIT!BF7 -> 21.8 | I11: =[1]SIT!BG7 -> -379.7
B12: TOTAL | C12: =SUM(C8:C11) -> 830 | E12: =SUM(E8:E11) -> 427.82 | F12: =SUM(F8:F11) -> 810 | H12: =SUM(H8:H11) -> 113.555 | I12: =SUM(I8:I11) -> -314.265
A13: 8 | B13: =[1]SIT!AZ56 -> *BM-101 | C13: =[1]SIT!BA56 -> 0 | D13: =[1]SIT!BB56 -> 74.3 | E13: =[1]SIT!BC56 -> 0 | F13: =[1]SIT!BD56 -> 0 | G13: =[1]SIT!BE56 -> 74.3 | H13: =[1]SIT!BF56 -> 0 | I13: =[1]SIT!BG56 -> 0 | J13: 113M-3
A14: 9 | B14: =[1]SIT!AZ58 -> *BM-104 | C14: =[1]SIT!BA58 -> 0 | D14: =[1]SIT!BB58 -> 20 | E14: =[1]SIT!BC58 -> 0 | F14: =[1]SIT!BD58 -> 0 | G14: =[1]SIT!BE58 -> 28.6 | H14: =[1]SIT!BF58 -> 0 | I14: =[1]SIT!BG58 -> 0
B15: TOTAL | C15: =SUM(C13:C14) -> 0 | E15: =SUM(E13:E14) -> 0 | F15: =SUM(F13:F14) -> 0 | H15: =SUM(H13:H14) -> 0 | I15: =SUM(I13:I14) -> 0
A16: 10 | B16: =[1]SIT!AQ5 -> 113M-04 | C16: =[1]SIT!AR5 -> 90 | D16: =[1]SIT!AS5 -> 93.6 | E16: =[1]SIT!AT5 -> 5.76 | F16: =[1]SIT!AU5 -> 80 | G16: =[1]SIT!AV5 -> 97.7 | H16: =[1]SIT!AW5 -> 1.84 | I16: =[1]SIT!AX5 -> -3.92 | J16: 113M-4
A17: 11 | B17: =[1]SIT!AQ27 -> 113M-70 | C17: =[1]SIT!AR27 -> 100 | D17: =[1]SIT!AS27 -> 80 | E17: =[1]SIT!AT27 -> 20 | F17: =[1]SIT!AU27 -> 75 | G17: =[1]SIT!AV27 -> 66.9 | H17: =[1]SIT!AW27 -> 24.825 | I17: =[1]SIT!AX27 -> 4.825
A18: 12 | B18: =[1]SIT!AZ4 -> 113M-81 | C18: =[1]SIT!BA4 -> 140 | D18: =[1]SIT!BB4 -> 86 | E18: =[1]SIT!BC4 -> 19.6 | F18: =[1]SIT!BD4 -> 115 | G18: =[1]SIT!BE4 -> 88.9 | H18: =[1]SIT!BF4 -> 12.765 | I18: =[1]SIT!BG4 -> -6.835
A19: 13 | B19: =[1]SIT!AZ5 -> 113M-82 | C19: =[1]SIT!BA5 -> 90 | D19: =[1]SIT!BB5 -> 51 | E19: =[1]SIT!BC5 -> 44.1 | F19: =[1]SIT!BD5 -> 80 | G19: =[1]SIT!BE5 -> 58.5 | H19: =[1]SIT!BF5 -> 33.2 | I19: =[1]SIT!BG5 -> -10.9
A20: 14 | B20: =[1]SIT!AZ6 -> 113M-83 | C20: =[1]SIT!BA6 -> 0 | D20: =[1]SIT!BB6 -> 94.6 | E20: =[1]SIT!BC6 -> 0 | F20: =[1]SIT!BD6 -> 0 | G20: =[1]SIT!BE6 -> 92.5 | H20: =[1]SIT!BF6 -> 0 | I20: =[1]SIT!BG6 -> 0
A21: 15 | B21: =[1]SIT!AZ61 -> BM-112 | C21: =[1]SIT!BA61 -> 70 | D21: =[1]SIT!BB61 -> 50 | E21: =[1]SIT!BC61 -> 35 | F21: =[1]SIT!BD61 -> 60 | G21: =[1]SIT!BE61 -> 39 | H21: =[1]SIT!BF61 -> 36.6 | I21: =[1]SIT!BG61 -> 1.6
B22: TOTAL | C22: =SUM(C16:C21) -> 490 | E22: =SUM(E16:E21) -> 124.46 | F22: =SUM(F16:F21) -> 410 | H22: =SUM(H16:H21) -> 109.23 | I22: =SUM(I16:I21) -> -15.23
A23: 16 | B23: =[1]SIT!AZ8 -> 113M-86 S.T. | C23: =[1]SIT!BA8 -> 60 | D23: =[1]SIT!BB8 -> 30 | E23: =[1]SIT!BC8 -> 42 | F23: =[1]SIT!BD8 -> 60 | G23: =[1]SIT!BE8 -> 40.9 | H23: =[1]SIT!BF8 -> 35.46 | I23: =[1]SIT!BG8 -> -6.54 | J23: 113M-6
A24: 17 | B24: =[1]SIT!AZ27 -> 113M-116 | C24: =[1]SIT!BA27 -> 80 | D24: =[1]SIT!BB27 -> 48.9 | E24: =[1]SIT!BC27 -> 40.88 | F24: =[1]SIT!BD27 -> 70 | G24: =[1]SIT!BE27 -> 96 | H24: =[1]SIT!BF27 -> 2.8 | I24: =[1]SIT!BG27 -> -38.08
B25: TOTAL | C25: =SUM(C23:C24) -> 140 | E25: =SUM(E23:E24) -> 82.88 | F25: =SUM(F23:F24) -> 130 | H25: =SUM(H23:H24) -> 38.26 | I25: =SUM(I23:I24) -> -44.62
A26: 18 | B26: =[1]SIT!AQ22 -> 113M-59 | C26: =[1]SIT!AR22 -> 170 | D26: =[1]SIT!AS22 -> 90.8 | E26: =[1]SIT!AT22 -> 15.64 | F26: =[1]SIT!AU22 -> 170 | G26: =[1]SIT!AV22 -> 82.9 | H26: =[1]SIT!AW22 -> 29.07 | I26: =[1]SIT!AX22 -> 13.43 | J26: 113M-7
A27: 19 | B27: =[1]SIT!AQ34 -> 113M-79 H | C27: =[1]SIT!AR34 -> 50 | D27: =[1]SIT!AS34 -> 53.2 | E27: =[1]SIT!AT34 -> 23.4 | F27: =[1]SIT!AU34 -> 50 | G27: =[1]SIT!AV34 -> 82.2 | H27: =[1]SIT!AW34 -> 8.9 | I27: =[1]SIT!AX34 -> -14.5
A28: 20 | B28: =[1]SIT!AZ10 -> 113M-91 | C28: =[1]SIT!BA10 -> 70 | D28: =[1]SIT!BB10 -> 71.2 | E28: =[1]SIT!BC10 -> 20.16 | F28: =[1]SIT!BD10 -> 70 | G28: =[1]SIT!BE10 -> 71.2 | H28: =[1]SIT!BF10 -> 20.16 | I28: =[1]SIT!BG10 -> 0
A29: 21 | B29: =[1]SIT!AZ16 -> 113M-101 | C29: =[1]SIT!BA16 -> 0 | D29: =[1]SIT!BB16 -> 0 | E29: =[1]SIT!BC16 -> 0 | F29: =[1]SIT!BD16 -> 30 | G29: =[1]SIT!BE16 -> 0.8 | H29: =[1]SIT!BF16 -> 29.76 | I29: =[1]SIT!BG16 -> 29.76
A30: 22 | B30: 113M-104 | C30: =[1]SIT!BA19 -> 45 | D30: =[1]SIT!BB19 -> 50 | E30: =[1]SIT!BC19 -> 22.5 | F30: =[1]SIT!BD19 -> 50 | G30: =[1]SIT!BE19 -> 37.2 | H30: =[1]SIT!BF19 -> 31.4 | I30: =[1]SIT!BG19 -> 8.9
A31: 23 | B31: 113M-117 | C31: =[1]SIT!BA28 -> 40 | D31: =[1]SIT!BB28 -> 46.5 | E31: =[1]SIT!BC28 -> 21.4 | F31: =[1]SIT!BD28 -> 50 | G31: =[1]SIT!BE28 -> 42.4 | H31: =[1]SIT!BF28 -> 28.8 | I31: =[1]SIT!BG28 -> 7.4 | BZ31: =SUM(#REF!) -> #REF! | CA31: =SUM((BY31*(1-BZ31/100))) -> #REF! | CB31: 550 | CC31: =SUM(#REF!) -> #REF! | CD31: =SUM((CB31*(1-CC31/100))) -> #REF! | CE31: =SUM(-(BY31*(1-BZ31/100))+(CB31*(1-CC31/100))) -> #REF! | CF31: 113M-101 | CG31: =SUM(#REF!) -> #REF! | CH31: =SUM(#REF!) -> #REF! | CI31: =SUM((CG31*(1-CH31/100))) -> #REF! | CJ31: 550 | CK31: =SUM(#REF!) -> #REF! | CL31: =SUM((CJ31*(1-CK31/100))) -> #REF! | CM31: =SUM(-(CG31*(1-CH31/100))+(CJ31*(1-CK31/100))) -> #REF! | CN31: 113M-101 | CO31: =SUM(BC66) -> 0 | CP31: =SUM(#REF!) -> #REF! | CQ31: =SUM((CO31*(1-CP31/100))) -> #REF! | CR31: 550 | CS31: =SUM(#REF!) -> #REF! | CT31: =SUM((CR31*(1-CS31/100))) -> #REF! | CU31: =SUM(-(CO31*(1-CP31/100))+(CR31*(1-CS31/100))) -> #REF! | CV31: 113M-101 | CW31: =SUM(BK66) -> 0 | CX31: =SUM(#REF!) -> #REF! | CY31: =SUM((CW31*(1-CX31/100))) -> #REF! | CZ31: 550 | DA31: =SUM(#REF!) -> #REF! | DB31: =SUM((CZ31*(1-DA31/100))) -> #REF! | DC31: =SUM(-(CW31*(1-CX31/100))+(CZ31*(1-DA31/100))) -> #REF! | DD31: 113M-101 | DE31: =SUM(BS66) -> 0 | DF31: =SUM(#REF!) -> #REF! | DG31: =SUM((DE31*(1-DF31/100))) -> #REF! | DH31: 550 | DI31: =SUM(#REF!) -> #REF! | DJ31: =SUM((DH31*(1-DI31/100))) -> #REF! | DK31: =SUM(-(DE31*(1-DF31/100))+(DH31*(1-DI31/100))) -> #REF! | DL31: 113M-101 | DM31: =SUM(CA66) -> 0 | DN31: =SUM(#REF!) -> #REF! | DO31: =SUM((DM31*(1-DN31/100))) -> #REF! | DP31: 550 | DQ31: =SUM(#REF!) -> #REF! | DR31: =SUM((DP31*(1-DQ31/100))) -> #REF! | DS31: =SUM(-(DM31*(1-DN31/100))+(DP31*(1-DQ31/100))) -> #REF! | DT31: 113M-101 | DU31: =SUM(CI66) -> 0 | DV31: =SUM(#REF!) -> #REF! | DW31: =SUM((DU31*(1-DV31/100))) -> #REF! | DX31: 550 | DY31: =SUM(#REF!) -> #REF! | DZ31: =SUM((DX31*(1-DY31/100))) -> #REF! | EA31: =SUM(-(DU31*(1-DV31/100))+(DX31*(1-DY31/100))) -> #REF! | EB31: 113M-101 | EC31: =SUM(CQ66) -> 0 | ED31: =SUM(#REF!) -> #REF! | EE31: =SUM((EC31*(1-ED31/100))) -> #REF! | EF31: 550 | EG31: =SUM(#REF!) -> #REF! | EH31: =SUM((EF31*(1-EG31/100))) -> #REF! | EI31: =SUM(-(EC31*(1-ED31/100))+(EF31*(1-EG31/100))) -> #REF! | EJ31: 113M-101 | EK31: =SUM(CY66) -> 0 | EL31: =SUM(#REF!) -> #REF! | EM31: =SUM((EK31*(1-EL31/100))) -> #REF! | EN31: 550 | EO31: =SUM(#REF!) -> #REF! | EP31: =SUM((EN31*(1-EO31/100))) -> #REF! | EQ31: =SUM(-(EK31*(1-EL31/100))+(EN31*(1-EO31/100))) -> #REF! | ER31: 113M-101 | ES31: =SUM(DG66) -> 0 | ET31: =SUM(#REF!) -> #REF! | EU31: =SUM((ES31*(1-ET31/100))) -> #REF! | EV31: 550 | EW31: =SUM(#REF!) -> #REF! | EX31: =SUM((EV31*(1-EW31/100))) -> #REF! | EY31: =SUM(-(ES31*(1-ET31/100))+(EV31*(1-EW31/100))) -> #REF! | EZ31: 113M-101 | FA31: =SUM(DO66) -> 0 | FB31: =SUM(#REF!) -> #REF! | FC31: =SUM((FA31*(1-FB31/100))) -> #REF! | FD31: 550 | FE31: =SUM(#REF!) -> #REF! | FF31: =SUM((FD31*(1-FE31/100))) -> #REF! | FG31: =SUM(-(FA31*(1-FB31/100))+(FD31*(1-FE31/100))) -> #REF! | FH31: 113M-101 | FI31: =SUM(DW66) -> 0 | FJ31: =SUM(#REF!) -> #REF! | FK31: =SUM((FI31*(1-FJ31/100))) -> #REF! | FL31: 550 | FM31: =SUM(#REF!) -> #REF! | FN31: =SUM((FL31*(1-FM31/100))) -> #REF! | FO31: =SUM(-(FI31*(1-FJ31/100))+(FL31*(1-FM31/100))) -> #REF! | FP31: 113M-101 | FQ31: =SUM(EE66) -> 0 | FR31: =SUM(#REF!) -> #REF! | FS31: =SUM((FQ31*(1-FR31/100))) -> #REF! | FT31: 550 | FU31: =SUM(#REF!) -> #REF! | FV31: =SUM((FT31*(1-FU31/100))) -> #REF! | FW31: =SUM(-(FQ31*(1-FR31/100))+(FT31*(1-FU31/100))) -> #REF! | FX31: 113M-101 | FY31: =SUM(EM66) -> 0 | FZ31: =SUM(#REF!) -> #REF! | GA31: =SUM((FY31*(1-FZ31/100))) -> #REF! | GB31: 550 | GC31: =SUM(#REF!) -> #REF! | GD31: =SUM((GB31*(1-GC31/100))) -> #REF! | GE31: =SUM(-(FY31*(1-FZ31/100))+(GB31*(1-GC31/100))) -> #REF! | GF31: 113M-101 | GG31: =SUM(EU66) -> 0 | GH31: =SUM(#REF!) -> #REF! | GI31: =SUM((GG31*(1-GH31/100))) -> #REF! | GJ31: 550 | GK31: =SUM(#REF!) -> #REF! | GL31: =SUM((GJ31*(1-GK31/100))) -> #REF! | GM31: =SUM(-(GG31*(1-GH31/100))+(GJ31*(1-GK31/100))) -> #REF! | GN31: 113M-101 | GO31: =SUM(FC66) -> 0 | GP31: =SUM(#REF!) -> #REF! | GQ31: =SUM((GO31*(1-GP31/100))) -> #REF! | GR31: 550 | GS31: =SUM(#REF!) -> #REF! | GT31: =SUM((GR31*(1-GS31/100))) -> #REF! | GU31: =SUM(-(GO31*(1-GP31/100))+(GR31*(1-GS31/100))) -> #REF! | GV31: 113M-101 | GW31: =SUM(FK66) -> 0 | GX31: =SUM(#REF!) -> #REF! | GY31: =SUM((GW31*(1-GX31/100))) -> #REF! | GZ31: 550 | HA31: =SUM(#REF!) -> #REF! | HB31: =SUM((GZ31*(1-HA31/100))) -> #REF! | HC31: =SUM(-(GW31*(1-GX31/100))+(GZ31*(1-HA31/100))) -> #REF! | HD31: 113M-101 | HE31: =SUM(FS66) -> 0 | HF31: =SUM(#REF!) -> #REF! | HG31: =SUM((HE31*(1-HF31/100))) -> #REF! | HH31: 550 | HI31: =SUM(#REF!) -> #REF! | HJ31: =SUM((HH31*(1-HI31/100))) -> #REF! | HK31: =SUM(-(HE31*(1-HF31/100))+(HH31*(1-HI31/100))) -> #REF! | HL31: 113M-101 | HM31: =SUM(GA66) -> 0 | HN31: =SUM(#REF!) -> #REF! | HO31: =SUM((HM31*(1-HN31/100))) -> #REF! | HP31: 550 | HQ31: =SUM(#REF!) -> #REF! | HR31: =SUM((HP31*(1-HQ31/100))) -> #REF! | HS31: =SUM(-(HM31*(1-HN31/100))+(HP31*(1-HQ31/100))) -> #REF! | HT31: 113M-101 | HU31: =SUM(GI66) -> 0 | HV31: =SUM(#REF!) -> #REF! | HW31: =SUM((HU31*(1-HV31/100))) -> #REF! | HX31: 550 | HY31: =SUM(#REF!) -> #REF! | HZ31: =SUM((HX31*(1-HY31/100))) -> #REF! | IA31: =SUM(-(HU31*(1-HV31/100))+(HX31*(1-HY31/100))) -> #REF! | IB31: 113M-101 | IC31: =SUM(GQ66) -> 0 | ID31: =SUM(#REF!) -> #REF! | IE31: =SUM((IC31*(1-ID31/100))) -> #REF! | IF31: 550 | IG31: =SUM(#REF!) -> #REF! | IH31: =SUM((IF31*(1-IG31/100))) -> #REF! | II31: =SUM(-(IC31*(1-ID31/100))+(IF31*(1-IG31/100))) -> #REF! | IJ31: 113M-101 | IK31: =SUM(GY66) -> 0 | IL31: =SUM(#REF!) -> #REF! | IM31: =SUM((IK31*(1-IL31/100))) -> #REF! | IN31: 550 | IO31: =SUM(#REF!) -> #REF! | IP31: =SUM((IN31*(1-IO31/100))) -> #REF! | IQ31: =SUM(-(IK31*(1-IL31/100))+(IN31*(1-IO31/100))) -> #REF!
A32: 24 | B32: =[1]SIT!AZ34 -> 113M-123 | C32: =[1]SIT!BA34 -> 180 | D32: =[1]SIT!BB34 -> 4 | E32: =[1]SIT!BC34 -> 172.8 | F32: =[1]SIT!BD34 -> 180 | G32: =[1]SIT!BE34 -> 4.5 | H32: =[1]SIT!BF34 -> 171.9 | I32: =[1]SIT!BG34 -> -0.9
B33: TOTAL | C33: =SUM(C26:C32) -> 555 | E33: =SUM(E26:E31) -> 103.1 | F33: =SUM(F26:F32) -> 600 | H33: =SUM(H26:H32) -> 319.99 | I33: =SUM(I26:I32) -> 44.09
A34: 25 | B34: =[1]SIT!AQ6 -> 113M-08B | C34: =[1]SIT!AR6 -> 150 | D34: =[1]SIT!AS6 -> 73.2 | E34: =[1]SIT!AT6 -> 40.2 | F34: =[1]SIT!AU6 -> 130 | G34: =[1]SIT!AV6 -> 87.2 | H34: =[1]SIT!AW6 -> 16.64 | I34: =[1]SIT!AX6 -> -23.56 | J34: 113M-8
A35: 26 | B35: =[1]SIT!AQ28 -> 113M-71 | C35: =[1]SIT!AR28 -> 130 | D35: =[1]SIT!AS28 -> 87 | E35: =[1]SIT!AT28 -> 16.9 | F35: =[1]SIT!AU28 -> 130 | G35: =[1]SIT!AV28 -> 91.4 | H35: =[1]SIT!AW28 -> 11.18 | I35: =[1]SIT!AX28 -> -5.72
A36: 27 | B36: =[1]SIT!AQ33 -> 113M-78 | C36: =[1]SIT!AR33 -> 80 | D36: =[1]SIT!AS33 -> 46 | E36: =[1]SIT!AT33 -> 43.2 | F36: =[1]SIT!AU33 -> 70 | G36: =[1]SIT!AV33 -> 68.6 | H36: =[1]SIT!AW33 -> 21.98 | I36: =[1]SIT!AX33 -> -21.22
A37: 28 | B37: =[1]SIT!AZ15 -> 113M-100 | C37: =[1]SIT!BA15 -> 100 | D37: =[1]SIT!BB15 -> 58.2 | E37: =[1]SIT!BC15 -> 41.8 | F37: =[1]SIT!BD15 -> 100 | G37: =[1]SIT!BE15 -> 58.2 | H37: =[1]SIT!BF15 -> 41.8 | I37: =[1]SIT!BG15 -> 0
A38: 29 | B38: =[1]SIT!AZ20 -> 113M-107 | C38: =[1]SIT!BA20 -> 60 | D38: =[1]SIT!BB20 -> 80 | E38: =[1]SIT!BC20 -> 12 | F38: =[1]SIT!BD20 -> 60 | G38: =[1]SIT!BE20 -> 90.7 | H38: =[1]SIT!BF20 -> 5.58 | I38: =[1]SIT!BG20 -> -6.42
A39: 30 | B39: =[1]SIT!AZ22 -> 113M-109 | C39: =[1]SIT!BA22 -> 90 | D39: =[1]SIT!BB22 -> 90 | E39: =[1]SIT!BC22 -> 9 | F39: =[1]SIT!BD22 -> 90 | G39: =[1]SIT!BE22 -> 50.8 | H39: =[1]SIT!BF22 -> 44.28 | I39: =[1]SIT!BG22 -> 35.28
A40: 31 | B40: =[1]SIT!AZ23 -> *113M-110 | C40: =[1]SIT!BA23 -> 0 | D40: =[1]SIT!BB23 -> 94.6 | E40: =[1]SIT!BC23 -> 0 | F40: =[1]SIT!BD23 -> 0 | G40: =[1]SIT!BE23 -> 93.7 | H40: =[1]SIT!BF23 -> 0 | I40: =[1]SIT!BG23 -> 0
B41: =[1]SIT!AZ35 -> 113M-124 | C41: =[1]SIT!BA35 -> 80 | D41: =[1]SIT!BB35 -> 50 | E41: =[1]SIT!BC35 -> 40 | F41: =[1]SIT!BD35 -> 100 | G41: =[1]SIT!BE35 -> 1.6 | H41: =[1]SIT!BF35 -> 98.4 | I41: =[1]SIT!BG35 -> 58.4
...

Sheet DATA BASE
H6: REP. DATA | K6: ACT. DATA | AD6: Panel
A7: Well | B7: Status | C7: Reporting Status | D7: shut down reason | E7: LOCATION | F7: PLAT. | G7: POWER FEEDER | H7: RATE , M3/D | I7: W.C % | J7: REP. NET | K7: ACT , M3/D2 | L7: ACT.W.C % | M7: ACT NET | N7: GOR M3/M3 | O7: GAS MMS CF/D | P7: WHP,PSI | Q7: AMP | R7: HZ | S7: MOTOR , HP | T7: DESGIN AMP. | U7: DH Pump | V7: STG | W7: CH. VALVE | X7: PACKER | Y7: S.V | Z7: LAST W.O | AA7: REMARKS | AB7: SUB-MARINE CABLE | AC7: EARTHED CABLE | AD7: Panel Type | AE7: DH Control Line | AF7: CHEMICAL | AG7: RAISER | AH7: SIGNAL LIGHT | AI7: REMARKS2
A8: 113M-01 RE. | B8: Producer | C8: Reported | D8: PROD. | E8: M-1 | F8: PP3 | G8: PP3 | H8: 75 | I8: 66 | J8: =Database[[#This Row],[RATE , M3/D]]*(1-I8/100) -> 25.5 | K8: 85 | L8: 68.6 | M8: =Database[[#This Row],[ACT , M3/D2]]*(1-L8/100) -> 26.69 | N8: 60 | O8: 0.06 | P8: 400 | Q8: 30 | S8: 99 | T8: 36 | U8: P-6 | V8: 376 | Z8: 43444 | AA8: KEEP PINCHING | AB8: No | AH8: =VLOOKUP(E8,' Data Lists'!$Z$3:$AA$31,2,) -> IN SERVICE | AK8: Cond. B
A9: 113M-02 | B9: Producer | C9: Reported | D9: PROD. | E9: M-2 | F9: =VLOOKUP(E9,' Data Lists'!$T$3:$U$31,2,) -> PP3 | G9: MWP-2 | H9: 80 | I9: 79.6 | J9: =Database[[#This Row],[RATE , M3/D]]*(1-I9/100) -> 16.32 | K9: 80 | L9: 0.8 | M9: =Database[[#This Row],[ACT , M3/D2]]*(1-L9/100) -> 79.36 | N9: 87 | O9: 0.11 | P9: 400 | Q9: 20 | S9: 83.5 | T9: 29 | U9: D800N | V9: 260 | Z9: 44083 | AB9: SUB MARINE | AH9: =VLOOKUP(E9,' Data Lists'!$Z$3:$AA$31,2,) -> IN SERVICE | AK9: Cond. B
A10: 113M-03 | B10: Producer | C10: Not Reported | D10: PROD. | E10: M-3 | F10: PP2 | G10: PP2 | H10: 0 | I10: 0 | J10: =Database[[#This Row],[RATE , M3/D]]*(1-I10/100) -> 0 | K10: 50 | L10: 57.3 | M10: =Database[[#This Row],[ACT , M3/D2]]*(1-L10/100) -> 21.35 | AH10: =VLOOKUP(E10,' Data Lists'!$Z$3:$AA$31,2,) -> OUT OF SERVICE
A11: 113M-04 | B11: Producer | C11: Reported | D11: PROD. | E11: M-4 | F11: =VLOOKUP(E11,' Data Lists'!$T$3:$U$31,2,) -> PP2 | G11: PP2 | H11: 90 | I11: 93.6 | J11: =Database[[#This Row],[RATE , M3/D]]*(1-I11/100) -> 5.76 | K11: 80 | L11: 97.7 | M11: =Database[[#This Row],[ACT , M3/D2]]*(1-L11/100) -> 1.84 | N11: 91 | O11: 0.05 | P11: 400 | Q11: 36 | S11: 99 | T11: 36 | U11: FLEX-10 | V11: 245 | Z11: 43684 | AB11: REDA | AH11: =VLOOKUP(E11,' Data Lists'!$Z$3:$AA$31,2,) -> IN SERVICE
A12: 113M-08 BIS | B12: Waiting Work Over | C12: Reported | D12: PROD. | E12: M-8 | F12: =VLOOKUP(E12,' Data Lists'!$T$3:$U$31,2,) -> PP2 | G12: PP2 | H12: 150 | I12: 73.2 | J12: =Database[[#This Row],[RATE , M3/D]]*(1-I12/100) -> 40.2 | K12: 130 | L12: 87.2 | M12: =Database[[#This Row],[ACT , M3/D2]]*(1-L12/100) -> 16.64 | N12: 163 | O12: 0.32 | P12: 180 | Q12: 44 | S12: 187 | T12: 64 | U12: GN-1600 | V12: 198 | Z12: 43145 | AB12: SUB MARINE | AH12: =VLOOKUP(E12,' Data Lists'!$Z$3:$AA$31,2,) -> OUT OF SERVICE
A13: 113M-18 | B13: Producer | C13: Reported | D13: PROD. | E13: CL 18/20 | F13: =VLOOKUP(E13,' Data Lists'!$T$3:$U$31,2,) -> PP3 | G13: PP3 | H13: 400 | I13: 84.2 | J13: =Database[[#This Row],[RATE , M3/D]]*(1-I13/100) -> 63.2 | K13: 400 | L13: 85.6 | M13: =Database[[#This Row],[ACT , M3/D2]]*(1-L13/100) -> 57.6 | N13: 75 | O13: 0.26 | P13: 400 | Q13: 90 | S13: 334 | T13: 111 | U13: GN-3200 | V13: 270 | Z13: 44101 | AB13: No | AH13: =VLOOKUP(E13,' Data Lists'!$Z$3:$AA$31,2,) -> IN SERVICE
A14: 113M-26 | B14: Producer | C14: Reported | D14: PROD. | E14: M-26 | F14: =VLOOKUP(E14,' Data Lists'!$T$3:$U$31,2,) -> PP3 | G14: pp3 | H14: 80 | I14: 93.6 | J14: =Database[[#This Row],[RATE , M3/D]]*(1-I14/100) -> 5.12 | K14: 0 | L14: 88 | M14: =Database[[#This Row],[ACT , M3/D2]]*(1-L14/100) -> 0 | N14: 86 | O14: 0.03 | P14: 400 | Q14: 39 | S14: 100 | T14: 34 | U14: FLEX-10 | V14: 238 | Z14: 43830 | AB14: No | AH14: =VLOOKUP(E14,' Data Lists'!$Z$3:$AA$31,2,) -> OUT OF SERVICE
A15: 113M-29 | B15: Producer | C15: Reported | D15: PROD. | E15: SCP-2 | F15: =VLOOKUP(E15,' Data Lists'!$T$3:$U$31,2,) -> PP3 | G15: pp3 | H15: 120 | I15: 70 | J15: =Database[[#This Row],[RATE , M3/D]]*(1-I15/100) -> 36 | K15: 95 | L15: 54.1 | M15: =Database[[#This Row],[ACT , M3/D2]]*(1-L15/100) -> 43.605 | N15: 141 | O15: 0.29 | P15: 100 | Q15: 50 | U15: FLEX-10 | V15: 293 | Z15: 43172 | AB15: No | AH15: =VLOOKUP(E15,' Data Lists'!$Z$3:$AA$31,2,) -> IN SERVICE
A16: 113M-30 | B16: Waiting Work Over | C16: Reported | D16: PROD. | E16: SCP-2 | F16: =VLOOKUP(E16,' Data Lists'!$T$3:$U$31,2,) -> PP3 | G16: pp3 | H16: 0 | I16: 87 | J16: =Database[[#This Row],[RATE , M3/D]]*(1-I16/100) -> 0 | K16: 0 | L16: 68.9 | M16: =Database[[#This Row],[ACT , M3/D2]]*(1-L16/100) -> 0 | N16: 0 | O16: 0 | P16: 0 | Q16: 0 | S16: 208 | T16: 65 | U16: GN-2100 | V16: 249 | Z16: 42619 | AB16: No | AH16: =VLOOKUP(E16,' Data Lists'!$Z$3:$AA$31,2,) -> IN SERVICE
A17: 113M-35 | B17: Producer | C17: Not Reported | D17: PROD. | E17: M-35 | F17: =VLOOKUP(E17,' Data Lists'!$T$3:$U$31,2,) -> PP2 | G17: PP2 | H17: 0 | I17: 80 | J17: =Database[[#This Row],[RATE , M3/D]]*(1-I17/100) -> 0 | K17: 200 | L17: 97.2 | M17: =Database[[#This Row],[ACT , M3/D2]]*(1-L17/100) -> 5.6 | N17: 0 | O17: 0 | P17: 150 | Q17: 38 | S17: 138 | T17: 44 | U17: GC-1200 | V17: 240 | Z17: 42722 | AB17: No | AH17: =VLOOKUP(E17,' Data Lists'!$Z$3:$AA$31,2,) -> OUT OF SERVICE
A18: 113M-40 | B18: Waiting Work Over | C18: Not Reported | D18: PROD. | E18: M-35 | F18: =VLOOKUP(E18,' Data Lists'!$T$3:$U$31,2,) -> PP2 | G18: PP2 | J18: =Database[[#This Row],[RATE , M3/D]]*(1-I18/100) -> 0 | K18: 0 | L18: 0 | M18: =Database[[#This Row],[ACT , M3/D2]]*(1-L18/100) -> 0 | N18: 0 | O18: 0 | P18: 0 | Q18: 0 | S18: 100 | T18: 36 | U18: P-6 | V18: 310 | Z18: 42740 | AB18: No | AH18: =VLOOKUP(E18,' Data Lists'!$Z$3:$AA$31,2,) -> OUT OF SERVICE
A19: 113M-42 | B19: Waiting Work Over | C19: Reported | D19: PROD. | E19: SCP-2 | F19: =VLOOKUP(E19,' Data Lists'!$T$3:$U$31,2,) -> PP3 | G19: PP3 | H19: 0 | I19: 90 | J19: =Database[[#This Row],[RATE , M3/D]]*(1-I19/100) -> 0 | K19: 0 | L19: 0 | M19: =Database[[#This Row],[ACT , M3/D2]]*(1-L19/100) -> 0 | N19: 0 | O19: 0 | P19: 100 | Q19: 119 | S19: 374 | T19: 127 | U19: GC-3500 | V19: 234 | Z19: 42629 | AB19: No | AH19: =VLOOKUP(E19,' Data Lists'!$Z$3:$AA$31,2,) -> IN SERVICE
A20: 113M-45 | B20: Waiting Work Over | C20: Reported | D20: PROD. | E20: SCP-2 | F20: =VLOOKUP(E20,' Data Lists'!$T$3:$U$31,2,) -> PP3 | G20: PP3 | H20: 50 | I20: 60 | J20: =Database[[#This Row],[RATE , M3/D]]*(1-I20/100) -> 20 | K20: 60 | L20: 95 | M20: =Database[[#This Row],[ACT , M3/D2]]*(1-L20/100) -> 3 | N20: 342 | O20: 0.12 | P20: 100 | Q20: 21 | S20: 73 | T20: 27 | U20: P-4 | V20: 320 | Z20: 42026 | AB20: No | AH20: =VLOOKUP(E20,' Data Lists'!$Z$3:$AA$31,2,) -> IN SERVICE
A21: 113M-46 | B21: Producer | C21: Reported | D21: PROD. | E21: M-2 | F21: =VLOOKUP(E21,' Data Lists'!$T$3:$U$31,2,) -> PP3 | G21: MWP-2 | H21: 200 | I21: 95 | J21: =Database[[#This Row],[RATE , M3/D]]*(1-I21/100) -> 10 | K21: 185 | L21: 93.3 | M21: =Database[[#This Row],[ACT , M3/D2]]*(1-L21/100) -> 12.395 | N21: 90 | O21: 0.11 | P21: 400 | Q21: 62 | S21: 187 | T21: 59 | U21: GC-1700 | V21: 238 | Z21: 43638 | AB21: Yes | AH21: =VLOOKUP(E21,' Data Lists'!$Z$3:$AA$31,2,) -> IN SERVICE
A22: 113M-48 | B22: Producer | C22: Reported | D22: PROD. | E22: MWP-1 | F22: =VLOOKUP(E22,' Data Lists'!$T$3:$U$31,2,) -> PP2 | G22: PP2 | H22: 80 | I22: 41 | J22: =Database[[#This Row],[RATE , M3/D]]*(1-I22/100) -> 47.2 | K22: 80 | L22: 36.8 | M22: =Database[[#This Row],[ACT , M3/D2]]*(1-L22/100) -> 50.56 | N22: 110 | O22: 0.16 | P22: 400 | Q22: 22 | S22: 133 | T22: 30.5 | U22: D800N | V22: 309 | Z22: 43414 | AB22: No | AH22: =VLOOKUP(E22,' Data Lists'!$Z$3:$AA$31,2,) -> IN SERVICE
A23: 113M-49 | B23: Waiting Work Over | C23: Reported | D23: PROD. | E23: MWP-1 | F23: =VLOOKUP(E23,' Data Lists'!$T$3:$U$31,2,) -> PP2 | G23: PP2 | H23: 90 | I23: 83.5 | J23: =Database[[#This Row],[RATE , M3/D]]*(1-I23/100) -> 14.85 | K23: 90 | L23: 84.2 | M23: =Database[[#This Row],[ACT , M3/D2]]*(1-L23/100) -> 14.22 | N23: 100 | O23: 0.22 | P23: 120 | Q23: 33 | S23: 133 | T23: 46 | U23: D1150N | V23: 299 | Z23: 42642 | AB23: No | AH23: =VLOOKUP(E23,' Data Lists'!$Z$3:$AA$31,2,) -> IN SERVICE
A24: 113M-50 | B24: Waiting Work Over | C24: Reported | D24: PROD. | E24: MWP-1 | F24: =VLOOKUP(E24,' Data Lists'!$T$3:$U$31,2,) -> PP2 | G24: PP2 | H24: 30 | I24: 3.6 | J24: =Database[[#This Row],[RATE , M3/D]]*(1-I24/100) -> 28.92 | K24: 30 | L24: 4 | M24: =Database[[#This Row],[ACT , M3/D2]]*(1-L24/100) -> 28.8 | N24: 63 | O24: 0.03 | P24: 400 | Q24: 12 | S24: 67 | T24: 24 | U24: WD-450 | V24: 450 | Z24: 43973 | AB24: NO | AH24: =VLOOKUP(E24,' Data Lists'!$Z$3:$AA$31,2,) -> IN SERVICE
A25: 113M-55 | B25: Waiting Work Over | C25: Reported | D25: PROD. | E25: MWP-2 | F25: =VLOOKUP(E25,' Data Lists'!$T$3:$U$31,2,) -> PP3 | G25: MWP-2 | H25: 45 | I25: 67.4 | J25: =Database[[#This Row],[RATE , M3/D]]*(1-I25/100) -> 14.67 | K25: 50 | L25: 20.3 | M25: =Database[[#This Row],[ACT , M3/D2]]*(1-L25/100) -> 39.85 | N25: 27 | O25: 0.03 | P25: 400 | Q25: 13 | S25: 66.7 | T25: 24 | U25: WD-450 | V25: 436 | Z25: 44094 | AB25: No | AH25: =VLOOKUP(E25,' Data Lists'!$Z$3:$AA$31,2,) -> IN SERVICE
A26: 113M-57 | B26: Producer | C26: Reported | D26: PROD. | E26: MWP-2 | F26: =VLOOKUP(E26,' Data Lists'!$T$3:$U$31,2,) -> PP3 | G26: MWP-2 | H26: 180 | I26: 66 | J26: =Database[[#This Row],[RATE , M3/D]]*(1-I26/100) -> 61.2 | K26: 180 | L26: 78.2 | M26: =Database[[#This Row],[ACT , M3/D2]]*(1-L26/100) -> 39.24 | N26: 42 | O26: 0.03 | P26: 400 | Q26: 40 | S26: 150 | T26: 50 | U26: WG-1600 | V26: 195 | Z26: 43825 | AB26: No | AH26: =VLOOKUP(E26,' Data Lists'!$Z$3:$AA$31,2,) -> IN SERVICE
A27: 113M-58 | B27: Producer | C27: Reported | D27: PROD. | E27: MWP-2 | F27: =VLOOKUP(E27,' Data Lists'!$T$3:$U$31,2,) -> PP3 | G27: MWP-2 | H27: 130 | I27: 91.3 | J27: =Database[[#This Row],[RATE , M3/D]]*(1-I27/100) -> 11.31 | K27: 130 | L27: 91.3 | M27: =Database[[#This Row],[ACT , M3/D2]]*(1-L27/100) -> 11.31 | N27: 83 | O27: 0.08 | P27: 400 | Q27: 29 | S27: 133 | T27: 46 | U27: WD-1300 | V27: 358 | Z27: 44055 | AB27: No | AH27: =VLOOKUP(E27,' Data Lists'!$Z$3:$AA$31,2,) -> IN SERVICE
A28: 113M-59 | B28: Producer | C28: Reported | D28: PROD. | E28: M-7 | F28: =VLOOKUP(E28,' Data Lists'!$T$3:$U$31,2,) -> PP2 | G28: RLP | H28: 170 | I28: 90.8 | J28: =Database[[#This Row],[RATE , M3/D]]*(1-I28/100) -> 15.64 | K28: 170 | L28: 82.9 | M28: =Database[[#This Row],[ACT , M3/D2]]*(1-L28/100) -> 29.07 | N28: 103 | O28: 0.025 | P28: 400 | Q28: 44 | S28: 167 | T28: 60 | U28: B400-1750 | V28: 458 | Z28: 43721 | AB28: SUB MARINE | AH28: =VLOOKUP(E28,' Data Lists'!$Z$3:$AA$31,2,) -> IN SERVICE
A29: 113M-65 | B29: Producer | C29: Reported | D29: PROD. | E29: CL 18/20 | F29: =VLOOKUP(E29,' Data Lists'!$T$3:$U$31,2,) -> PP3 | G29: MWP-2 | H29: 0 | I29: 95 | J29: =Database[[#This Row],[RATE , M3/D]]*(1-I29/100) -> 0 | K29: 0 | L29: 92 | M29: =Database[[#This Row],[ACT , M3/D2]]*(1-L29/100) -> 0 | N29: 0 | O29: 0 | P29: 400 | Q29: 31 | S29: 116.7 | T29: 39 | U29: WF400-1250 | V29: 328 | Z29: 43356 | AB29: No | AH29: =VLOOKUP(E29,' Data Lists'!$Z$3:$AA$31,2,) -> IN SERVICE
A30: 113M-66 | B30: Producer | C30: Reported | D30: PROD. | E30: CL 18/20 | F30: =VLOOKUP(E30,' Data Lists'!$T$3:$U$31,2,) -> PP3 | G30: PP3 | H30: 150 | I30: 90 | J30: =Database[[#This Row],[RATE , M3/D]]*(1-I30/100) -> 15 | K30: 140 | L30: 98 | M30: =Database[[#This Row],[ACT , M3/D2]]*(1-L30/100) -> 2.8 | N30: 89 | O30: 0.06 | P30: 500 | Q30: 32 | S30: 133 | T30: 46 | U30: WF400-1250 | V30: 365 | Z30: 43544 | AB30: No | AH30: =VLOOKUP(E30,' Data Lists'!$Z$3:$AA$31,2,) -> IN SERVICE
... A32: 113M-68 ST | B32: Producer | C32: Reported | D32: PROD. | E32: BM-1 | F32: =VLOOKUP(E32,' Data Lists'!$T$3:$U$31,2,) -> PP2 | G32: PP2 | H32: 0 | I32: 98 | J32: =Database[[#This Row],[RATE , M3/D]]*(1-I32/100) -> 0 | K32: 0 | L32: 96 | M32: =Database[[#This Row],[ACT , M3/D2]]*(1-L32/100) -> 0 | N32: 0 | O32: 0 | P32: 0 | Q32: 25 | S32: 100 | T32: 35 | U32: B400-700 | V32: 377 | Z32: 43715 | AB32: REDA | AH32: =VLOOKUP(E32,' Data Lists'!$Z$3:$AA$31,2,) -> IN SERVICE
A33: 113M-70 | B33: Producer | C33: Reported | D33: PROD. | E33: M-4 | F33: =VLOOKUP(E33,' Data Lists'!$T$3:$U$31,2,) -> PP2 | G33: RLP | H33: 100 | I33: 80 | J33: =Database[[#This Row],[RATE , M3/D]]*(1-I33/100) -> 20 | K33: 75 | L33: 66.9 | M33: =Database[[#This Row],[ACT , M3/D2]]*(1-L33/100) -> 24.825 | N33: 69 | O33: 0.14 | P33: 400 | Q33: 29 | S33: 93 | T33: 32 | U33: B400-1050 | V33: 332 | Z33: 42845 | AB33: REDA | AD33: TRANSFORMER | AH33: =VLOOKUP(E33,' Data Lists'!$Z$3:$AA$31,2,) -> IN SERVICE
A34: 113M-71 | B34: Producer | C34: Reported | D34: PROD. | E34: M-8 | F34: =VLOOKUP(E34,' Data Lists'!$T$3:$U$31,2,) -> PP2 | G34: RLP | H34: 0 | I34: 87 | J34: =Database[[#This Row],[RATE , M3/D]]*(1-I34/100) -> 0 | K34: 0 | L34: 91.4 | M34: =Database[[#This Row],[ACT , M3/D2]]*(1-L34/100) -> 0 | N34: 0 | O34: 0 | P34: 400 | Q34: 46 | S34: 187.5 | T34: 62 | U34: B516-1600 | V34: 255 | Z34: 43152 | AB34: REDA | AH34: =VLOOKUP(E34,' Data Lists'!$Z$3:$AA$31,2,) -> OUT OF SERVICE
A35: 113M-72 | B35: Waiting Work Over | C35: Reported | D35: PROD. | E35: CL-12 | F35: =VLOOKUP(E35,' Data Lists'!$T$3:$U$31,2,) -> PP2 | G35: RLP | H35: 0 | I35: 0 | J35: =Database[[#This Row],[RATE , M3/D]]*(1-I35/100) -> 0 | K35: 35 | L35: 67.8 | M35: =Database[[#This Row],[ACT , M3/D2]]*(1-L35/100) -> 11.27 | P35: 400 | Q35: 18 | S35: 58 | T35: 22 | U35: P-4 | V35: 248 | Z35: 24/3/2019 | AB35: REDA | AD35: TRANSFORMER | AH35: =VLOOKUP(E35,' Data Lists'!$Z$3:$AA$31,2,) -> IN SERVICE
A36: 113M-74 | B36: Producer | C36: Reported | D36: PROD. | E36: CL 18/20 | F36: =VLOOKUP(E36,' Data Lists'!$T$3:$U$31,2,) -> PP3 | G36: MWP-2 | H36: 150 | I36: 80 | J36: =Database[[#This Row],[RATE , M3/D]]*(1-I36/100) -> 30 | K36: 180 | L36: 69.6 | M36: =Database[[#This Row],[ACT , M3/D2]]*(1-L36/100) -> 54.72 | N36: 33 | O36: 0.08 | P36: 400 | Q36: 30 | S36: 150 | T36: 50 | U36: WD-1300 | V36: 370 | Z36: 24/3/2019 | AB36: No | AH36: =VLOOKUP(E36,' Data Lists'!$Z$3:$AA$31,2,) -> IN SERVICE
A37: 113M-76 | B37: Producer | C37: Reported | D37: PROD. | E37: MWP-2 | F37: =VLOOKUP(E37,' Data Lists'!$T$3:$U$31,2,) -> PP3 | G37: MWP-2 | H37: 80 | I37: 93 | J37: =Database[[#This Row],[RATE , M3/D]]*(1-I37/100) -> 5.6 | K37: 80 | L37: 74.3 | M37: =Database[[#This Row],[ACT , M3/D2]]*(1-L37/100) -> 20.56 | N37: 265 | O37: 0.32 | P37: 130 | Q37: 31 | S37: 104 | T37: 39 | U37: FLEX-10 | V37: 285 | Z37: 43326 | AB37: No | AH37: =VLOOKUP(E37,' Data Lists'!$Z$3:$AA$31,2,) -> IN SERVICE
A38: 113M-77 H | B38: Producer | C38: Reported | D38: PROD. | E38: M-1 | F38: =VLOOKUP(E38,' Data Lists'!$T$3:$U$31,2,) -> PP2/PP3 | G38: PP3 | H38: 170 | I38: 85 | J38: =Database[[#This Row],[RATE , M3/D]]*(1-I38/100) -> 25.5 | K38: 170 | L38: 85.4 | M38: =Database[[#This Row],[ACT , M3/D2]]*(1-L38/100) -> 24.82 | N38: 71 | O38: 0.04 | P38: 500 | Q38: 37 | S38: 146 | T38: 48 | U38: GN-1600 | V38: 201 | Z38: 42538 | AB38: No | AH38: =VLOOKUP(E38,' Data Lists'!$Z$3:$AA$31,2,) -> IN SERVICE
A39: 113M-78 | B39: Producer | C39: Reported | D39: PROD. | E39: M-8 | F39: =VLOOKUP(E39,' Data Lists'!$T$3:$U$31,2,) -> PP2 | G39: PP2 | H39: 80 | I39: 46 | J39: =Database[[#This Row],[RATE , M3/D]]*(1-I39/100) -> 43.2 | K39: 70 | L39: 68.8 | M39: =Database[[#This Row],[ACT , M3/D2]]*(1-L39/100) -> 21.84 | N39: 117 | O39: 0.08 | P39: 400 | Q39: 22 | S39: 83.5 | T39: 28.5 | U39: WD-650 | V39: 510 | Z39: 43628 | AB39: No | AH39: =VLOOKUP(E39,' Data Lists'!$Z$3:$AA$31,2,) -> OUT OF SERVICE
A40: 113M-79 | B40: Producer | C40: Reported | D40: PROD. | E40: M-7 | F40: =VLOOKUP(E40,' Data Lists'!$T$3:$U$31,2,) -> PP2 | G40: PP2 | H40: 50 | I40: 53.2 | J40: =Database[[#This Row],[RATE , M3/D]]*(1-I40/100) -> 23.4 | K40: 50 | L40: 82.2 | M40: =Database[[#This Row],[ACT , M3/D2]]*(1-L40/100) -> 8.9 | N40: 68 | O40: 0.019 | P40: 400 | Q40: 19 | S40: 83 | T40: 28.5 | U40: WD-850 | V40: 272 | Z40: 43429 | AB40: SUB MARINE | AH40: =VLOOKUP(E40,' Data Lists'!$Z$3:$AA$31,2,) -> IN SERVICE
A41: 113M-80 | B41: Producer | C41: Reported | D41: PROD. | E41: CL 18/20 | F41: =VLOOKUP(E41,' Data Lists'!$T$3:$U$31,2,) -> PP3 | G41: PP3 | H41: 90 | I41: 50.7 | J41: =Database[[#This Row],[RATE , M3/D]]*(1-I41/100) -> 44.37 | K41: 100 | L41: 65.5 | M41: =Database[[#This Row],[ACT , M3/D2]]*(1-L41/100) -> 34.5 | N41: 74 | O41: 0.012 | P41: 500 | Q41: 23 | S41: 95 | T41: 30 | U41: FLEX-10 | V41: 190 | Z41: 43577 | AB41: No | AH41: =VLOOKUP(E41,' Data Lists'!$Z$3:$AA$31,2,) -> IN SERVICE
A42: 113M-81 | B42: Producer | C42: Reported | D42: PROD. | E42: M-4 | F42: =VLOOKUP(E42,' Data Lists'!$T$3:$U$31,2,) -> PP2 | G42: PP2 | H42: 140 | I42: 86 | J42: =Database[[#This Row],[RATE , M3/D]]*(1-I42/100) -> 19.6 | K42: 115 | L42: 88.9 | M42: =Database[[#This Row],[ACT , M3/D2]]*(1-L42/100) -> 12.765 | N42: 208 | O42: 0.14 | P42: 400 | Q42: 31 | S42: 125 | T42: 45 | U42: B400-1050 | V42: 400 | Z42: 42861 | AB42: SUB MARINE | AH42: =VLOOKUP(E42,' Data Lists'!$Z$3:$AA$31,2,) -> IN SERVICE
A43: 113M-82 | B43: Producer | C43: Reported | D43: PROD. | E43: M-4 | F43: =VLOOKUP(E43,' Data Lists'!$T$3:$U$31,2,) -> PP2 | G43: PP2 | H43: 90 | I43: 51 | J43: =Database[[#This Row],[RATE , M3/D]]*(1-I43/100) -> 44.1 | K43: 80 | L43: 58.5 | M43: =Database[[#This Row],[ACT , M3/D2]]*(1-L43/100) -> 33.2 | N43: 118 | O43: 0.15 | P43: 500 | Q43: 24 | S43: 104 | T43: 39 | U43: P-8 | V43: 259 | Z43: 43311 | AB43: SUB MARINE | AH43: =VLOOKUP(E43,' Data Lists'!$Z$3:$AA$31,2,) -> IN SERVICE
A44: 113M-83 | B44: Producer | C44: Reported | D44: PROD. | E44: M-4 | F44: =VLOOKUP(E44,' Data Lists'!$T$3:$U$31,2,) -> PP2 | G44: PP2 | H44: 0 | I44: 94.6 | J44: =Database[[#This Row],[RATE , M3/D]]*(1-I44/100) -> 0 | K44: 0 | L44: 92.5 | M44: =Database[[#This Row],[ACT , M3/D2]]*(1-L44/100) -> 0 | N44: 0 | O44: 0 | P44: 400 | Q44: 14 | S44: 66.7 | T44: 24 | U44: WD-450 | V44: 422 | Z44: 43508 | AB44: SUB MARINE | AH44: =VLOOKUP(E44,' Data Lists'!$Z$3:$AA$31,2,) -> IN SERVICE
A45: 113M-84 | B45: Producer | C45: Reported | D45: PROD. | E45: M-2 | F45: =VLOOKUP(E45,' Data Lists'!$T$3:$U$31,2,) -> PP3 | G45: PP2 | H45: 550 | I45: 26.2 | J45: =Database[[#This Row],[RATE , M3/D]]*(1-I45/100) -> 405.9 | K45: 545 | L45: 96 | M45: =Database[[#This Row],[ACT , M3/D2]]*(1-L45/100) -> 21.8 | N45: 114 | O45: 0.38 | P45: 200 | Q45: 90 | S45: 115 | T45: 115 | U45: B513-6000 | V45: 340 | Z45: 43842 | AB45: SUB MARINE | AD45: TRANSFORMER | AH45: =VLOOKUP(E45,' Data Lists'!$Z$3:$AA$31,2,) -> IN SERVICE
A46: 113M-85 | B46: Producer | C46: Not Reported | D46: PROD. | J46: =Database[[#This Row],[RATE , M3/D]]*(1-I46/100) -> 0 | M46: =Database[[#This Row],[ACT , M3/D2]]*(1-L46/100) -> 0 | AH46: =VLOOKUP(E46,' Data Lists'!$Z$3:$AA$31,2,) -> #N/A
...

Sheet FIRST PAGE
A1: OFFSHORE OIL SITATION 27/10/2020
A2: plt | B2: ACT , M3/D2 | C2: ACT.W.C % | D2: ACT NET | E2: GAS MMS CF/D | F2: plt | G2: ACT , M3/D2 | H2: ACT.W.C % | I2: ACT NET | J2: GAS MMS CF/D | K2: PLATF.
A3: M-3 | B3: ='PLT. WELL BLANCE'!E16 -> 290 | D3: ='PLT. WELL BLANCE'!G16 -> 129.59 | E3: ='PLT. WELL BLANCE'!$K$16 -> 0 | F3: BM-1 | G3: ='PLT. WELL BLANCE'!E77 -> 310 | H3: =(1-I3/G3)*100 -> 12.125806 | I3: ='PLT. WELL BLANCE'!G77 -> 272.41 | J3: ='PLT. WELL BLANCE'!$K$77 -> 0.22 | K3: PP2
A4: M-4 | B4: ='PLT. WELL BLANCE'!E23 -> 410 | C4: =(1-D4/B4)*100 -> 73.358537 | D4: ='PLT. WELL BLANCE'!G23 -> 109.23 | E4: ='PLT. WELL BLANCE'!$K$23 -> 0.62 | F4: BM-6 | G4: ='PLT. WELL BLANCE'!E87 -> 150 | H4: =(1-I4/G4)*100 -> 52.413333 | I4: ='PLT. WELL BLANCE'!G87 -> 71.38 | J4: ='PLT. WELL BLANCE'!$K$87 -> 0.97
A5: M-6 | B5: ='PLT. WELL BLANCE'!E28 -> 130 | C5: =(1-D5/B5)*100 -> 70.569231 | D5: ='PLT. WELL BLANCE'!G28 -> 38.26 | E5: ='PLT. WELL BLANCE'!$K$28 -> 0.62 | F5: BM-7 | G5: ='PLT. WELL BLANCE'!E97 -> 655 | H5: =(1-I5/G5)*100 -> 63.729771 | I5: ='PLT. WELL BLANCE'!G97 -> 237.57 | J5: ='PLT. WELL BLANCE'!$K$97 -> 1.43
A6: M-7 | B6: ='PLT. WELL BLANCE'!E35 -> 420 | C6: =(1-D6/B6)*100 -> 54.930952 | D6: ='PLT. WELL BLANCE'!G35 -> 189.29 | E6: ='PLT. WELL BLANCE'!$K$35 -> 1.424 | F6: BM 15/27 | G6: ='PLT. WELL BLANCE'!E101 -> 50 | H6: =(1-I6/G6)*100 -> 33.1 | I6: ='PLT. WELL BLANCE'!G101 -> 33.45 | J6: ='PLT. WELL BLANCE'!$K$101 -> 0.04
A7: M-8 | B7: ='PLT. WELL BLANCE'!E44 -> 550 | C7: =(1-D7/B7)*100 -> 58.447273 | D7: ='PLT. WELL BLANCE'!G44 -> 228.54 | E7: ='PLT. WELL BLANCE'!$K$44 -> 1.33 | F7: BM 23/25 | G7: ='PLT. WELL BLANCE'!E109 -> 400 | H7: =(1-I7/G7)*100 -> 97.5 | I7: ='PLT. WELL BLANCE'!G109 -> 10 | J7: ='PLT. WELL BLANCE'!$K$109 -> 0.05
A8: M-10 | B8: ='PLT. WELL BLANCE'!E46 -> 210 | C8: =(1-D8/B8)*100 -> 79.6 | D8: ='PLT. WELL BLANCE'!G46 -> 42.84 | E8: ='PLT. WELL BLANCE'!$K$46 -> 0.14 | F8: BMNE-1 | G8: ='PLT. WELL BLANCE'!E111 -> 80 | I8: ='PLT. WELL BLANCE'!G111 -> 14.32 | J8: ='PLT. WELL BLANCE'!$K$112 -> 0
A9: M-35 | B9: ='PLT. WELL BLANCE'!E67 -> 200 | D9: ='PLT. WELL BLANCE'!G67 -> 5.6 | E9: ='PLT. WELL BLANCE'!$K$67 -> 0 | F9: MWP-1 | G9: ='PLT. WELL BLANCE'!E118 -> 260 | H9: =(1-I9/G9)*100 -> 52.307692 | I9: ='PLT. WELL BLANCE'!G118 -> 124 | J9: ='PLT. WELL BLANCE'!$K$118 -> 0.56
A10: CL-12 | B10: ='PLT. WELL BLANCE'!E69 -> 35 | C10: =(1-D10/B10)*100 -> 67.8 | D10: ='PLT. WELL BLANCE'!G69 -> 11.27 | E10: ='PLT. WELL BLANCE'!$K$69 -> 0
B11: =SUM(B3:B10) -> 2245 | D11: =SUM(D3:D10) -> 754.62 | E11: =SUM(E3:E10) -> 4.134 | G11: =SUM(G3:G10) -> 1905 | I11: =SUM(I3:I10) -> 763.13 | J11: =SUM(J3:J10) -> 3.27
A12: M-1 | B12: ='PLT. WELL BLANCE'!E7 -> 455 | C12: =(1-D12/B12)*100 -> 46.832967 | D12: ='PLT. WELL BLANCE'!G7 -> 241.91 | E12: ='PLT. WELL BLANCE'!$K$7 -> 0.13 | F12: M-26 | G12: ='PLT. WELL BLANCE'!E64 -> 315 | H12: =(1-I12/G12)*100 -> 36.673016 | I12: ='PLT. WELL BLANCE'!G64 -> 199.48 | J12: ='PLT. WELL BLANCE'!$K$64 -> 0.37 | K12: PP3
A13: M-2 | B13: ='PLT. WELL BLANCE'!E12 -> 810 | C13: =(1-D13/B13)*100 -> 85.980864 | D13: ='PLT. WELL BLANCE'!G12 -> 113.555 | E13: ='PLT. WELL BLANCE'!$K$12 -> 0.6 | F13: MWP-2 | G13: ='PLT. WELL BLANCE'!E125 -> 940 | H13: =(1-I13/G13)*100 -> 78.844681 | I13: ='PLT. WELL BLANCE'!G125 -> 198.86 | J13: ='PLT. WELL BLANCE'!$K$125 -> 0.95
A14: CL 18/20 | B14: ='PLT. WELL BLANCE'!E60 -> 1480 | C14: =(1-D14/B14)*100 -> 66.608784 | D14: ='PLT. WELL BLANCE'!G60 -> 494.19 | E14: ='PLT. WELL BLANCE'!$K$60 -> 1.642 | F14: SCP-2 | G14: ='total pltf'!E24 -> 155 | H14: ='total pltf'!F24 -> 69.932258 | I14: ='total pltf'!G24 -> 46.605 | J14: ='total pltf'!$I$24 -> 0.41
B15: =SUM(B12:B14) -> 2745 | D15: =SUM(D12:D14) -> 849.655 | E15: =SUM(E12:E14) -> 2.372 | G15: =SUM(G12:G14) -> 1410 | I15: =SUM(I12:I14) -> 444.945 | J15: =SUM(J12:J14) -> 1.73
A16: BM-3 | B16: ='PLT. WELL BLANCE'!E82 -> 300 | C16: =(1-D16/B16)*100 -> 48.94 | D16: ='PLT. WELL BLANCE'!G82 -> 153.18 | E16: ='PLT. WELL BLANCE'!$K$82 -> 1.05 | F16: MWP-4 | G16: ='PLT. WELL BLANCE'!E144 -> 505 | H16: =(1-I16/G16)*100 -> 88.30396 | I16: ='PLT. WELL BLANCE'!G144 -> 59.065 | J16: ='PLT. WELL BLANCE'!$K$144 -> 0.68 | K16: D-10
A17: BMNW-1 | B17: ='PLT. WELL BLANCE'!E107 -> 120 | C17: =(1-D17/B17)*100 -> 71 | D17: ='PLT. WELL BLANCE'!G107 -> 34.8 | E17: ='PLT. WELL BLANCE'!$K$107 -> 0 | F17: MWP-5 | G17: ='PLT. WELL BLANCE'!E159 -> 1265 | H17: =(1-I17/G17)*100 -> 55.44664 | I17: ='PLT. WELL BLANCE'!G159 -> 563.6 | J17: ='PLT. WELL BLANCE'!$K$159 -> 2.82
A18: MWP-3 | B18: ='PLT. WELL BLANCE'!E137 -> 480 | C18: =(1-D18/B18)*100 -> 51.241667 | D18: ='PLT. WELL BLANCE'!G137 -> 234.04 | E18: ='PLT. WELL BLANCE'!$K$137 -> 2.35 | F18: SCP-1 | G18: ='PLT. WELL BLANCE'!E169 -> #REF! | H18: =(1-I18/G18)*100 -> #REF! | I18: ='PLT. WELL BLANCE'!G169 -> #REF! | J18: ='PLT. WELL BLANCE'!$K$169 -> #REF!
B19: =SUM(B16:B18) -> 900 | D19: =SUM(D16:D18) -> 422.02 | E19: =SUM(E16:E18) -> 3.4 | G19: =SUM(G16:G18) -> #REF! | I19: =SUM(I16:I18) -> #REF! | J19: =SUM(J16:J18) -> #REF!
A20: R/G | B20: ='PLT. WELL BLANCE'!E181 -> 1700 | C20: =(1-D20/B20)*100 -> 88.167059 | D20: ='PLT. WELL BLANCE'!G181 -> 201.16 | E20: ='PLT. WELL BLANCE'!$K$181 -> 1.27 | K20: =VLOOKUP(A20,' Data Lists'!$T$3:$U$31,2,) -> R/G
A22: plt | B22: ACT GROSS | D22: ACT.W.C | E22: % | F22: ACT NET | H22: GAS MMS CF/D
A23: PP2 | B23: =B11+G11 -> 4150 | C23: M3 | D23: =(1-F23/B23)*100 -> 63.427711 | E23: % | F23: =D11+I11 -> 1517.75 | G23: M3 | H23: =E11+J11 -> 7.404
B24: =B23*6.289 -> 26099.35 | C24: BBL | F24: =F23*6.289 -> 9545.1298 | G24: BBL
A25: PP3 | B25: =B15+G15 -> 4155 | C25: M3 | D25: =(1-F25/B25)*100 -> 68.842359 | E25: % | F25: =D15+I15 -> 1294.6 | G25: M3 | H25: =E15+J15 -> 4.102
B26: =B25*6.289 -> 26130.795 | C26: BBL | F26: =F25*6.289 -> 8141.7394 | G26: BBL
A27: D-10 | B27: =B19+G19 -> #REF! | C27: M3 | D27: =(1-F27/B27)*100 -> #REF! | E27: % | F27: =D19+I19 -> #REF! | G27: M3 | H27: =E19+J19 -> #REF!
B28: =B27*6.289 -> #REF! | C28: BBL | F28: =F27*6.289 -> #REF! | G28: BBL
A30: MARINE + R/G : REP. GROSS | C30: ='WELLS BLANCE'!$C$164 -> #REF! | E30: M3/D | F30: =C30*6.289 -> #REF! | H30: BBLS/D
A31: TOTAL MARINE REP NET | C31: ='WELLS BLANCE'!$C$165 -> #REF! | E31: M3/D | F31: =C31*6.283 -> #REF! | H31: BBLS/D
A32: TOTAL MARINE ACT GROSS | C32: ='WELLS BLANCE'!$C$166 -> #REF! | E32: M3/D | F32: =C32*6.289 -> #REF! | H32: BBLS/D
A33: TOTAL MARINE ACT NET | C33: ='WELLS BLANCE'!$C$167 -> #REF! | E33: M3/D | F33: =C33*6.289 -> #REF! | H33: BBLS/D
A34: RAS GARA ACT NET | C34: ='WELLS BLANCE'!$C$168 -> 201.16 | E34: M3/D | F34: =C34*6.289 -> 1265.0952 | H34: BBLS/D
A35: BELAYIM ACT NET | C35: ='WELLS BLANCE'!$C$169 -> #REF! | E35: M3/D | F35: =C35*6.289 -> #REF! | H35: BBLS/D
A36: MARINE GAS | C36: ='PLT. WELL BLANCE'!K185 -> #REF! | F36: MMS CF/D
A37: TOTAL PRODUCED WATER | C37: =C32-C33 -> #REF! | E37: M3/D | F37: =C37*6.289 -> #REF! | H37: BBLS/D
A38: DIFF MARINE ACT. , REP. NET | C38: =C31-C33 -> #REF! | E38: M3/D | F38: =C38*6.289 -> #REF! | H38: BBLS/D
A40: REPORTED WELLS | F40: NOT REPORTED WELLS
A41: NO. OF WELLS | D41: ='DATA BASE'!F157 -> 128 | F41: NO. OF WELLS | J41: ='DATA BASE'!$L$157 -> 18
A42: NO. OF PRODUCED | D42: ='DATA BASE'!$F$158 -> 98 | F42: PRODUCED | J42: ='DATA BASE'!$L$158 -> 12
A43: NO. OF WAITING W.O | D43: ='DATA BASE'!$F$159 -> 29 | F43: NO. OF WAITING W.O | J43: ='DATA BASE'!$L$159 -> 6
...

Sheet DOWN HOLE PUMP
A1: Well NO. | B1: WHP | C1: AMP | D1: GAS MMS CF/D | E1: GOR M3/M3 | F1: MOTOR HP | G1: AMP | H1: PUMP TYPE | I1: STG. | J1: LAST W.O
A2: ='DATA BASE'!A8 -> 113M-01 RE. | B2: ='DATA BASE'!P8 -> 400 | C2: ='DATA BASE'!Q8 -> 30 | D2: ='DATA BASE'!O8 -> 0.06 | E2: ='DATA BASE'!N8 -> 60 | F2: ='DATA BASE'!S8 -> 99 | G2: ='DATA BASE'!T8 -> 36 | H2: ='DATA BASE'!U8 -> P-6 | I2: ='DATA BASE'!V8 -> 376 | J2: ='DATA BASE'!Z8 -> 43444
A3: ='DATA BASE'!A9 -> 113M-02 | B3: ='DATA BASE'!P9 -> 400 | C3: ='DATA BASE'!Q9 -> 20 | D3: ='DATA BASE'!O9 -> 0.11 | E3: ='DATA BASE'!N9 -> 87 | F3: ='DATA BASE'!S9 -> 83.5 | G3: ='DATA BASE'!T9 -> 29 | H3: ='DATA BASE'!U9 -> D800N | I3: ='DATA BASE'!V9 -> 260 | J3: ='DATA BASE'!Z9 -> 44083
A4: ='DATA BASE'!A11 -> 113M-04 | B4: ='DATA BASE'!P11 -> 400 | C4: ='DATA BASE'!Q11 -> 36 | D4: ='DATA BASE'!O11 -> 0.05 | E4: ='DATA BASE'!N11 -> 91 | F4: ='DATA BASE'!S11 -> 99 | G4: ='DATA BASE'!T11 -> 36 | H4: ='DATA BASE'!U11 -> FLEX-10 | I4: ='DATA BASE'!V11 -> 245 | J4: ='DATA BASE'!Z11 -> 43684
A5: ='DATA BASE'!A12 -> 113M-08 BIS | B5: ='DATA BASE'!P12 -> 180 | C5: ='DATA BASE'!Q12 -> 44 | D5: ='DATA BASE'!O12 -> 0.32 | E5: ='DATA BASE'!N12 -> 163 | F5: ='DATA BASE'!S12 -> 187 | G5: ='DATA BASE'!T12 -> 64 | H5: ='DATA BASE'!U12 -> GN-1600 | I5: ='DATA BASE'!V12 -> 198 | J5: ='DATA BASE'!Z12 -> 43145
A6: ='DATA BASE'!A13 -> 113M-18 | B6: ='DATA BASE'!P13 -> 400 | C6: ='DATA BASE'!Q13 -> 90 | D6: ='DATA BASE'!O13 -> 0.26 | E6: ='DATA BASE'!N13 -> 75 | F6: ='DATA BASE'!S13 -> 334 | G6: ='DATA BASE'!T13 -> 111 | H6: ='DATA BASE'!U13 -> GN-3200 | I6: ='DATA BASE'!V13 -> 270 | J6: ='DATA BASE'!Z13 -> 44101
A7: ='DATA BASE'!A14 -> 113M-26 | B7: ='DATA BASE'!P14 -> 400 | C7: ='DATA BASE'!Q14 -> 39 | D7: ='DATA BASE'!O14 -> 0.03 | E7: ='DATA BASE'!N14 -> 86 | F7: ='DATA BASE'!S14 -> 100 | G7: ='DATA BASE'!T14 -> 34 | H7: ='DATA BASE'!U14 -> FLEX-10 | I7: ='DATA BASE'!V14 -> 238 | J7: ='DATA BASE'!Z14 -> 43830
A8: ='DATA BASE'!A15 -> 113M-29 | B8: ='DATA BASE'!P15 -> 100 | C8: ='DATA BASE'!Q15 -> 50 | D8: ='DATA BASE'!O15 -> 0.29 | E8: ='DATA BASE'!N15 -> 141 | F8: ='DATA BASE'!S15 -> 0 | G8: ='DATA BASE'!T15 -> 0 | H8: ='DATA BASE'!U15 -> FLEX-10 | I8: ='DATA BASE'!V15 -> 293 | J8: ='DATA BASE'!Z15 -> 43172
A9: ='DATA BASE'!A16 -> 113M-30 | B9: ='DATA BASE'!P16 -> 0 | C9: ='DATA BASE'!Q16 -> 0 | D9: ='DATA BASE'!O16 -> 0 | E9: ='DATA BASE'!N16 -> 0 | F9: ='DATA BASE'!S16 -> 208 | G9: ='DATA BASE'!T16 -> 65 | H9: ='DATA BASE'!U16 -> GN-2100 | I9: ='DATA BASE'!V16 -> 249 | J9: ='DATA BASE'!Z16 -> 42619
A10: ='DATA BASE'!A17 -> 113M-35 | B10: ='DATA BASE'!P17 -> 150 | C10: ='DATA BASE'!Q17 -> 38 | D10: ='DATA BASE'!O17 -> 0 | E10: ='DATA BASE'!N17 -> 0 | F10: ='DATA BASE'!S17 -> 138 | G10: ='DATA BASE'!T17 -> 44 | H10: ='DATA BASE'!U17 -> GC-1200 | I10: ='DATA BASE'!V17 -> 240 | J10: ='DATA BASE'!Z17 -> 42722
A11: ='DATA BASE'!A18 -> 113M-40 | B11: ='DATA BASE'!P18 -> 0 | C11: ='DATA BASE'!Q18 -> 0 | D11: ='DATA BASE'!O18 -> 0 | E11: ='DATA BASE'!N18 -> 0 | F11: ='DATA BASE'!S18 -> 100 | G11: ='DATA BASE'!T18 -> 36 | H11: ='DATA BASE'!U18 -> P-6 | I11: ='DATA BASE'!V18 -> 310 | J11: ='DATA BASE'!Z18 -> 42740
A12: ='DATA BASE'!A19 -> 113M-42 | B12: ='DATA BASE'!P19 -> 100 | C12: ='DATA BASE'!Q19 -> 119 | D12: ='DATA BASE'!O19 -> 0 | E12: ='DATA BASE'!N19 -> 0 | F12: ='DATA BASE'!S19 -> 374 | G12: ='DATA BASE'!T19 -> 127 | H12: ='DATA BASE'!U19 -> GC-3500 | I12: ='DATA BASE'!V19 -> 234 | J12: ='DATA BASE'!Z19 -> 42629
A13: ='DATA BASE'!A20 -> 113M-45 | B13: ='DATA BASE'!P20 -> 100 | C13: ='DATA BASE'!Q20 -> 21 | D13: ='DATA BASE'!O20 -> 0.12 | E13: ='DATA BASE'!N20 -> 342 | F13: ='DATA BASE'!S20 -> 73 | G13: ='DATA BASE'!T20 -> 27 | H13: ='DATA BASE'!U20 -> P-4 | I13: ='DATA BASE'!V20 -> 320 | J13: ='DATA BASE'!Z20 -> 42026
A14: ='DATA BASE'!A21 -> 113M-46 | B14: ='DATA BASE'!P21 -> 400 | C14: ='DATA BASE'!Q21 -> 62 | D14: ='DATA BASE'!O21 -> 0.11 | E14: ='DATA BASE'!N21 -> 90 | F14: ='DATA BASE'!S21 -> 187 | G14: ='DATA BASE'!T21 -> 59 | H14: ='DATA BASE'!U21 -> GC-1700 | I14: ='DATA BASE'!V21 -> 238 | J14: ='DATA BASE'!Z21 -> 43638
A15: ='DATA BASE'!A22 -> 113M-48 | B15: ='DATA BASE'!P22 -> 400 | C15: ='DATA BASE'!Q22 -> 22 | D15: ='DATA BASE'!O22 -> 0.16 | E15: ='DATA BASE'!N22 -> 110 | F15: ='DATA BASE'!S22 -> 133 | G15: ='DATA BASE'!T22 -> 30.5 | H15: ='DATA BASE'!U22 -> D800N | I15: ='DATA BASE'!V22 -> 309 | J15: ='DATA BASE'!Z22 -> 43414
... A29: ='DATA BASE'!A36 -> 113M-74 | B29: ='DATA BASE'!P36 -> 400 | C29: ='DATA BASE'!Q36 -> 30 | D29: ='DATA BASE'!O36 -> 0.08 | E29: ='DATA BASE'!N36 -> 33 | F29: ='DATA BASE'!S36 -> 150 | G29: ='DATA BASE'!T36 -> 50 | H29: ='DATA BASE'!U36 -> WD-1300 | I29: ='DATA BASE'!V36 -> 370 | J29: ='DATA BASE'!Z36 -> 24/3/2019
A30: Well NO. | B30: WHP | C30: AMP | D30: GAS MMS CF/D | E30: GOR M3/M3 | F30: MOTOR HP | G30: AMP | H30: PUMP TYPE | I30: STG. | J30: LAST W.O
A31: ='DATA BASE'!A37 -> 113M-76 | B31: ='DATA BASE'!P37 -> 130 | C31: ='DATA BASE'!Q37 -> 31 | D31: 0.32 | E31: ='DATA BASE'!N37 -> 265 | F31: ='DATA BASE'!S37 -> 104 | G31: ='DATA BASE'!Q37 -> 31 | H31: ='DATA BASE'!U37 -> FLEX-10 | I31: ='DATA BASE'!V37 -> 285 | J31: ='DATA BASE'!Z37 -> 43326
A32: ='DATA BASE'!A38 -> 113M-77 H | B32: ='DATA BASE'!P38 -> 500 | C32: ='DATA BASE'!Q38 -> 37 | D32: 0.04 | E32: ='DATA BASE'!N38 -> 71 | F32: ='DATA BASE'!S38 -> 146 | G32: ='DATA BASE'!Q38 -> 37 | H32: ='DATA BASE'!U38 -> GN-1600 | I32: ='DATA BASE'!V38 -> 201 | J32: ='DATA BASE'!Z38 -> 42538
A33: ='DATA BASE'!A39 -> 113M-78 | B33: ='DATA BASE'!P39 -> 400 | C33: ='DATA BASE'!Q39 -> 22 | D33: 0.08 | E33: ='DATA BASE'!N39 -> 117 | F33: ='DATA BASE'!S39 -> 83.5 | G33: ='DATA BASE'!Q39 -> 22 | H33: ='DATA BASE'!U39 -> WD-650 | I33: ='DATA BASE'!V39 -> 510 | J33: ='DATA BASE'!Z39 -> 43628
A34: ='DATA BASE'!A40 -> 113M-79 | B34: ='DATA BASE'!P40 -> 400 | C34: ='DATA BASE'!Q40 -> 19 | D34: 0.019 | E34: ='DATA BASE'!N40 -> 68 | F34: ='DATA BASE'!S40 -> 83 | G34: ='DATA BASE'!Q40 -> 19 | H34: ='DATA BASE'!U40 -> WD-850 | I34: ='DATA BASE'!V40 -> 272 | J34: ='DATA BASE'!Z40 -> 43429
A35: ='DATA BASE'!A41 -> 113M-80 | B35: ='DATA BASE'!P41 -> 500 | C35: ='DATA BASE'!Q41 -> 23 | D35: 0.012 | E35: ='DATA BASE'!N41 -> 74 | F35: ='DATA BASE'!S41 -> 95 | G35: ='DATA BASE'!Q41 -> 23 | H35: ='DATA BASE'!U41 -> FLEX-10 | I35: ='DATA BASE'!V41 -> 190 | J35: ='DATA BASE'!Z41 -> 43577
A36: ='DATA BASE'!A42 -> 113M-81 | B36: ='DATA BASE'!P42 -> 400 | C36: ='DATA BASE'!Q42 -> 31 | D36: 0.14 | E36: ='DATA BASE'!N42 -> 208 | F36: ='DATA BASE'!S42 -> 125 | G36: ='DATA BASE'!Q42 -> 31 | H36: ='DATA BASE'!U42 -> B400-1050 | I36: ='DATA BASE'!V42 -> 400 | J36: ='DATA BASE'!Z42 -> 42861
A37: ='DATA BASE'!A43 -> 113M-82 | B37: ='DATA BASE'!P43 -> 500 | C37: ='DATA BASE'!Q43 -> 24 | D37: 0.15 | E37: ='DATA BASE'!N43 -> 118 | F37: ='DATA BASE'!S43 -> 104 | G37: ='DATA BASE'!Q43 -> 24 | H37: ='DATA BASE'!U43 -> P-8 | I37: ='DATA BASE'!V43 -> 259 | J37: ='DATA BASE'!Z43 -> 43311
A38: ='DATA BASE'!A44 -> 113M-83 | B38: ='DATA BASE'!P44 -> 400 | C38: ='DATA BASE'!Q44 -> 14 | D38: 0 | E38: ='DATA BASE'!N44 -> 0 | F38: ='DATA BASE'!S44 -> 66.7 | G38: ='DATA BASE'!Q44 -> 14 | H38: ='DATA BASE'!U44 -> WD-450 | I38: ='DATA BASE'!V44 -> 422 | J38: ='DATA BASE'!Z44 -> 43508
A39: ='DATA BASE'!A45 -> 113M-84 | B39: ='DATA BASE'!P45 -> 200 | C39: ='DATA BASE'!Q45 -> 90 | D39: 0.38 | E39: ='DATA BASE'!N45 -> 114 | F39: ='DATA BASE'!S45 -> 115 | G39: ='DATA BASE'!Q45 -> 90 | H39: ='DATA BASE'!U45 -> B513-6000 | I39: ='DATA BASE'!V45 -> 340 | J39: ='DATA BASE'!Z45 -> 43842
A40: ='DATA BASE'!A47 -> 113M-86 | B40: ='DATA BASE'!P47 -> 500 | C40: ='DATA BASE'!Q47 -> 17 | D40: 0.19 | E40: ='DATA BASE'!N47 -> 385 | F40: ='DATA BASE'!S47 -> 64 | G40: ='DATA BASE'!Q47 -> 17 | H40: ='DATA BASE'!U47 -> FLEX 3.2 | I40: ='DATA BASE'!V47 -> 401 | J40: ='DATA BASE'!Z47 -> 43919
A41: ='DATA BASE'!A48 -> 113M-87 | B41: ='DATA BASE'!P48 -> 400 | C41: ='DATA BASE'!Q48 -> 19 | E41: ='DATA BASE'!N48 -> 0 | F41: ='DATA BASE'!S48 -> 64 | G41: ='DATA BASE'!Q48 -> 19 | H41: ='DATA BASE'!U48 -> FLEX 3.2 | I41: ='DATA BASE'!V48 -> 406 | J41: ='DATA BASE'!Z48 -> 43747
A42: ='DATA BASE'!A49 -> 113M-91 | B42: ='DATA BASE'!P49 -> 400 | C42: ='DATA BASE'!Q49 -> 27 | D42: 0.19 | E42: ='DATA BASE'!N49 -> 212 | F42: ='DATA BASE'!S49 -> 104 | G42: ='DATA BASE'!Q49 -> 27 | H42: ='DATA BASE'!U49 -> FLEX-10 | I42: ='DATA BASE'!V49 -> 190 | J42: ='DATA BASE'!Z49 -> 43928
A43: ='DATA BASE'!A50 -> 113M-94 | B43: ='DATA BASE'!P50 -> 0 | C43: ='DATA BASE'!Q50 -> 0 | D43: 0.03 | E43: ='DATA BASE'!N50 -> 70 | F43: ='DATA BASE'!S50 -> 97 | G43: ='DATA BASE'!Q50 -> 0 | H43: ='DATA BASE'!U50 -> B400-700 | I43: ='DATA BASE'!V50 -> 359 | J43: ='DATA BASE'!Z50 -> 44027
A44: ='DATA BASE'!A51 -> 113M-96 | B44: ='DATA BASE'!P51 -> 400 | C44: ='DATA BASE'!Q51 -> 35 | E44: ='DATA BASE'!N51 -> 0 | F44: ='DATA BASE'!S51 -> 150 | G44: ='DATA BASE'!Q51 -> 35 | H44: ='DATA BASE'!U51 -> B400-1250 | I44: ='DATA BASE'!V51 -> 377 | J44: ='DATA BASE'!Z51 -> 43894
A45: ='DATA BASE'!A52 -> 113M-97 | B45: ='DATA BASE'!P52 -> 400 | C45: ='DATA BASE'!Q52 -> 24 | D45: 0.06 | E45: ='DATA BASE'!N52 -> 62 | F45: ='DATA BASE'!S52 -> 64 | G45: ='DATA BASE'!Q52 -> 24 | H45: ='DATA BASE'!U52 -> FLEX 3.2 | I45: ='DATA BASE'!V52 -> 617 | J45: ='DATA BASE'!Z52 -> 44128
A46: ='DATA BASE'!A53 -> 113M-99 | B46: ='DATA BASE'!P53 -> 500 | C46: ='DATA BASE'!Q53 -> 47 | D46: 0.14 | E46: ='DATA BASE'!N53 -> 225 | F46: ='DATA BASE'!S53 -> 187 | G46: ='DATA BASE'!Q53 -> 47 | H46: ='DATA BASE'!U53 -> GC-1700 | I46: ='DATA BASE'!V53 -> 204 | J46: ='DATA BASE'!Z53 -> 43040
A47: ='DATA BASE'!A54 -> 113M-100 | B47: ='DATA BASE'!P54 -> 400 | C47: ='DATA BASE'!Q54 -> 32 | D47: 0.14 | E47: ='DATA BASE'!N54 -> 99 | F47: ='DATA BASE'!S54 -> 116.7 | G47: ='DATA BASE'!Q54 -> 32 | H47: ='DATA BASE'!U54 -> B400-1050 | I47: ='DATA BASE'!V54 -> 364 | J47: ='DATA BASE'!Z54 -> 44060
A48: ='DATA BASE'!A55 -> 113M-101 | B48: ='DATA BASE'!P55 -> 400 | C48: ='DATA BASE'!Q55 -> 13 | D48: 0.03 | E48: ='DATA BASE'!N55 -> 32 | F48: ='DATA BASE'!S55 -> 67 | G48: ='DATA BASE'!Q55 -> 13 | H48: ='DATA BASE'!U55 -> WD-450 | I48: ='DATA BASE'!V55 -> 472 | J48: ='DATA BASE'!Z55 -> 43391
A49: ='DATA BASE'!#REF! -> #REF! | B49: ='DATA BASE'!#REF! -> #REF! | C49: ='DATA BASE'!#REF! -> #REF! | D49: 0 | E49: ='DATA BASE'!#REF! -> #REF! | F49: ='DATA BASE'!#REF! -> #REF! | G49: ='DATA BASE'!#REF! -> #REF! | H49: ='DATA BASE'!#REF! -> #REF! | I49: ='DATA BASE'!#REF! -> #REF! | J49: ='DATA BASE'!#REF! -> #REF!
A50: ='DATA BASE'!A56 -> 113M-103 | B50: ='DATA BASE'!P56 -> 400 | C50: ='DATA BASE'!Q56 -> 99 | D50: 0.08 | E50: ='DATA BASE'!N56 -> 39 | F50: ='DATA BASE'!S56 -> 348 | G50: ='DATA BASE'!Q56 -> 99 | H50: ='DATA BASE'!U56 -> B513-3100 | I50: ='DATA BASE'!V56 -> 327 | J50: ='DATA BASE'!Z56 -> 44047
A51: ='DATA BASE'!#REF! -> #REF! | B51: ='DATA BASE'!#REF! -> #REF! | C51: ='DATA BASE'!#REF! -> #REF! | D51: 0.78 | E51: ='DATA BASE'!#REF! -> #REF! | F51: ='DATA BASE'!#REF! -> #REF! | G51: ='DATA BASE'!#REF! -> #REF! | H51: ='DATA BASE'!#REF! -> #REF! | I51: ='DATA BASE'!#REF! -> #REF! | J51: ='DATA BASE'!#REF! -> #REF!
A52: ='DATA BASE'!A57 -> 113M-107 | B52: ='DATA BASE'!P57 -> 400 | C52: ='DATA BASE'!Q57 -> 18 | D52: 0.19 | E52: ='DATA BASE'!N57 -> 281 | F52: ='DATA BASE'!S57 -> 66.7 | G52: ='DATA BASE'!Q57 -> 18 | H52: ='DATA BASE'!U57 -> WD-650 | I52: ='DATA BASE'!V57 -> 388 | J52: ='DATA BASE'!Z57 -> 43663
A53: ='DATA BASE'!#REF! -> #REF! | B53: ='DATA BASE'!#REF! -> #REF! | C53: ='DATA BASE'!#REF! -> #REF! | D53: 0.3 | E53: ='DATA BASE'!#REF! -> #REF! | F53: ='DATA BASE'!#REF! -> #REF! | G53: ='DATA BASE'!#REF! -> #REF! | H53: ='DATA BASE'!#REF! -> #REF! | I53: ='DATA BASE'!#REF! -> #REF! | J53: ='DATA BASE'!#REF! -> #REF!
...

Sheet w.c
A1: Well | B1: REP. W.C | C1: ACT. W.C | D1: Well | E1: REP. W.C | F1: ACT. W.C
A2: 113M-01 RE. | B2: ='DATA BASE'!I8 -> 66 | C2: ='DATA BASE'!L8 -> 68.6 | D2: 113M-70 | E2: ='DATA BASE'!I33 -> 80 | F2: ='DATA BASE'!L33 -> 66.9
A3: 113M-02 | B3: ='DATA BASE'!I9 -> 79.6 | C3: ='DATA BASE'!L9 -> 0.8 | D3: 113M-71 | E3: ='DATA BASE'!I34 -> 87 | F3: ='DATA BASE'!L34 -> 91.4
A4: 113M-04 | B4: ='DATA BASE'!I11 -> 93.6 | C4: ='DATA BASE'!L11 -> 97.7 | D4: 113M-72 | E4: ='DATA BASE'!I35 -> 0 | F4: ='DATA BASE'!L35 -> 67.8
A5: 113M-08 BIS | B5: ='DATA BASE'!I12 -> 73.2 | C5: ='DATA BASE'!L12 -> 87.2 | D5: 113M-74 | E5: ='DATA BASE'!I36 -> 80 | F5: ='DATA BASE'!L36 -> 69.6
A6: 113M-18 | B6: ='DATA BASE'!I13 -> 84.2 | C6: ='DATA BASE'!L13 -> 85.6 | D6: 113M-76 | E6: ='DATA BASE'!I37 -> 93 | F6: ='DATA BASE'!L37 -> 74.3
A7: 113M-26 | B7: ='DATA BASE'!I14 -> 93.6 | C7: ='DATA BASE'!L14 -> 88 | D7: 113M-77 H | E7: ='DATA BASE'!I38 -> 85 | F7: ='DATA BASE'!L38 -> 85.4
A8: 113M-29 | B8: ='DATA BASE'!I15 -> 70 | C8: ='DATA BASE'!L15 -> 54.1 | D8: 113M-78 | E8: ='DATA BASE'!I39 -> 46 | F8: ='DATA BASE'!L39 -> 68.8
A9: 113M-30 | B9: ='DATA BASE'!I16 -> 87 | C9: ='DATA BASE'!L16 -> 68.9 | D9: 113M-79 | E9: ='DATA BASE'!I40 -> 53.2 | F9: ='DATA BASE'!L40 -> 82.2
A10: 113M-35 | B10: ='DATA BASE'!I17 -> 80 | C10: ='DATA BASE'!L17 -> 97.2 | D10: 113M-80 | E10: ='DATA BASE'!I41 -> 50.7 | F10: ='DATA BASE'!L41 -> 65.5
A11: 113M-40 | B11: ='DATA BASE'!I18 -> 0 | C11: ='DATA BASE'!L18 -> 0 | D11: 113M-81 | E11: ='DATA BASE'!I42 -> 86 | F11: ='DATA BASE'!L42 -> 88.9
A12: 113M-42 | B12: ='DATA BASE'!I19 -> 90 | C12: ='DATA BASE'!L19 -> 0 | D12: 113M-82 | E12: ='DATA BASE'!I43 -> 51 | F12: ='DATA BASE'!L43 -> 58.5
A13: 113M-45 | B13: ='DATA BASE'!I20 -> 60 | C13: ='DATA BASE'!L20 -> 95 | D13: 113M-83 | E13: ='DATA BASE'!I44 -> 94.6 | F13: ='DATA BASE'!L44 -> 92.5
A14: 113M-46 | B14: ='DATA BASE'!I21 -> 95 | C14: ='DATA BASE'!L21 -> 93.3 | D14: 113M-84 | E14: ='DATA BASE'!I45 -> 26.2 | F14: ='DATA BASE'!L45 -> 96
A15: 113M-48 | B15: ='DATA BASE'!I22 -> 41 | C15: ='DATA BASE'!L22 -> 36.8 | D15: 113M-86 | E15: ='DATA BASE'!I47 -> 30 | F15: ='DATA BASE'!L47 -> 40.9
A16: 113M-49 | B16: ='DATA BASE'!I23 -> 83.5 | C16: ='DATA BASE'!L23 -> 84.2 | D16: 113M-87 | E16: ='DATA BASE'!I48 -> 0 | F16: ='DATA BASE'!L48 -> 77.2
A17: 113M-50 | B17: ='DATA BASE'!I24 -> 3.6 | C17: ='DATA BASE'!L24 -> 4 | D17: 113M-91 | E17: ='DATA BASE'!I49 -> 71.2 | F17: ='DATA BASE'!L49 -> 71.2
A18: 113M-55 | B18: ='DATA BASE'!I25 -> 67.4 | C18: ='DATA BASE'!L25 -> 20.3 | D18: 113M-94 | E18: ='DATA BASE'!I50 -> 80 | F18: ='DATA BASE'!L50 -> 76.7
A19: 113M-57 | B19: ='DATA BASE'!I26 -> 66 | C19: ='DATA BASE'!L26 -> 78.2 | D19: 113M-96 | E19: ='DATA BASE'!I51 -> 0 | F19: ='DATA BASE'!L51 -> 92
A20: 113M-58 | B20: ='DATA BASE'!I27 -> 91.3 | C20: ='DATA BASE'!L27 -> 91.3 | D20: 113M-97 | E20: ='DATA BASE'!I52 -> 50 | F20: ='DATA BASE'!L52 -> 50
A21: 113M-59 | B21: ='DATA BASE'!I28 -> 90.8 | C21: ='DATA BASE'!L28 -> 82.9 | D21: 113M-99 | E21: ='DATA BASE'!I53 -> 84 | F21: ='DATA BASE'!L53 -> 79.6
A22: 113-M65 | B22: ='DATA BASE'!I29 -> 95 | C22: ='DATA BASE'!L29 -> 92 | D22: 113M-100 | E22: ='DATA BASE'!I54 -> 58.2 | F22: ='DATA BASE'!L54 -> 58.2
A23: 113M-66 | B23: ='DATA BASE'!I30 -> 90 | C23: ='DATA BASE'!L30 -> 98 | D23: 113M-101 | E23: ='DATA BASE'!I55 -> 0 | F23: ='DATA BASE'!L55 -> 0.8
A24: 113M-67 | B24: ='DATA BASE'!I31 -> 97 | C24: ='DATA BASE'!L31 -> 92.7 | D24: 113M-102 | E24: ='DATA BASE'!#REF! -> #REF! | F24: ='DATA BASE'!#REF! -> #REF!
A25: 113M-68 ST | B25: ='DATA BASE'!I32 -> 98 | C25: ='DATA BASE'!L32 -> 96 | D25: 113M-103 | E25: ='DATA BASE'!I56 -> 69.3 | F25: ='DATA BASE'!L56 -> 95.6
A26: Well | B26: REP. W.C | C26: ACT. W.C | D26: Well | E26: REP. W.C | F26: ACT. W.C
A27: 113M-104 | B27: ='DATA BASE'!#REF! -> #REF! | C27: ='DATA BASE'!#REF! -> #REF! | D27: BM-15 RE. | E27: ='DATA BASE'!I75 -> 75 | F27: ='DATA BASE'!L75 -> 33.1
A28: 113M-107 | B28: ='DATA BASE'!I57 -> 80 | C28: ='DATA BASE'!L57 -> 90.7 | D28: BM-17 | E28: ='DATA BASE'!I76 -> 79 | F28: ='DATA BASE'!L76 -> 73.7
A29: 113M-108 | B29: ='DATA BASE'!#REF! -> #REF! | C29: ='DATA BASE'!#REF! -> #REF! | D29: BM-19 | E29: ='DATA BASE'!I77 -> 0 | F29: ='DATA BASE'!L77 -> 40.9
A30: 113M-109 | B30: ='DATA BASE'!I58 -> 50 | C30: ='DATA BASE'!L58 -> 50.8 | D30: BM-21 | E30: ='DATA BASE'!I78 -> 68.6 | F30: ='DATA BASE'!L78 -> 2.4
A31: 113M-110 | B31: ='DATA BASE'!I59 -> 94.6 | C31: ='DATA BASE'!L59 -> 93.7 | D31: BM-22 | E31: ='DATA BASE'!I79 -> 61.9 | F31: ='DATA BASE'!L79 -> 78.4
A32: 113M-112 | B32: ='DATA BASE'!I60 -> 71.6 | C32: ='DATA BASE'!L60 -> 80.2 | D32: BM-23 RE. | E32: ='DATA BASE'!I80 -> 100 | F32: ='DATA BASE'!L80 -> 97.5
A33: 113M-114 | B33: ='DATA BASE'!#REF! -> #REF! | C33: ='DATA BASE'!#REF! -> #REF! | D33: BM-26 | E33: ='DATA BASE'!I82 -> 45 | F33: ='DATA BASE'!L82 -> 67.9
A34: 113M-115 | B34: ='DATA BASE'!I61 -> 90.1 | C34: ='DATA BASE'!L61 -> 90.1 | D34: BM-27 | E34: ='DATA BASE'!I83 -> 1.2 | F34: ='DATA BASE'!L83 -> 37.6
A35: 113M-116 | B35: ='DATA BASE'!I62 -> 48.9 | C35: ='DATA BASE'!L62 -> 96 | D35: BM-29 | E35: ='DATA BASE'!#REF! -> #REF! | F35: ='DATA BASE'!#REF! -> #REF!
A36: 113M-117 | B36: ='DATA BASE'!I63 -> 46.5 | C36: ='DATA BASE'!L63 -> 42.4 | D36: BM-30 | E36: ='DATA BASE'!I85 -> 0 | F36: ='DATA BASE'!L85 -> 94.3
A37: 113M-118 | B37: ='DATA BASE'!I64 -> 50 | C37: ='DATA BASE'!L64 -> 3.2 | D37: BM-34 | E37: ='DATA BASE'!I86 -> 64.8 | F37: ='DATA BASE'!L86 -> 64.8
A38: 113M-119 | B38: ='DATA BASE'!I65 -> 1.6 | C38: ='DATA BASE'!L65 -> 7.3 | D38: BM-36 | E38: ='DATA BASE'!I87 -> 0 | F38: ='DATA BASE'!L87 -> 80
A39: 113M-120 | B39: ='DATA BASE'!I66 -> 27.8 | C39: ='DATA BASE'!L66 -> 4.8 | D39: BM-39S.T | E39: ='DATA BASE'!I89 -> 74 | F39: ='DATA BASE'!L89 -> 73.1
A40: 113M-121 | B40: ='DATA BASE'!I67 -> 13 | C40: ='DATA BASE'!L67 -> 0.8 | D40: BM-41 | E40: ='DATA BASE'!I90 -> 90 | F40: ='DATA BASE'!L90 -> 92
...

Sheet WELLS BLANCE
A1: Well NO. | B1: REP. RATE , M3/D | C1: REP.W.C % | D1: REP. NET M3/D | E1: ACT , M3/D2 | F1: ACT.W.C % | G1: ACT NET | H1: DIFF NET , M3/D
A2: 113M-01 RE. | B2: ='DATA BASE'!H8 -> 75 | C2: ='DATA BASE'!I8 -> 66 | D2: ='DATA BASE'!J8 -> 25.5 | E2: ='DATA BASE'!K8 -> 85 | F2: ='DATA BASE'!L8 -> 68.6 | G2: ='DATA BASE'!M8 -> 26.69 | H2: =G2-D2 -> 1.19
A3: 113M-02 | B3: ='DATA BASE'!H9 -> 80 | C3: ='DATA BASE'!I9 -> 79.6 | D3: ='DATA BASE'!J9 -> 16.32 | E3: ='DATA BASE'!K9 -> 80 | F3: ='DATA BASE'!L9 -> 0.8 | G3: ='DATA BASE'!M9 -> 79.36 | H3: =G3-D3 -> 63.04
A4: ='DATA BASE'!$A$10 -> 113M-03 | B4: ='DATA BASE'!H10 -> 0 | C4: ='DATA BASE'!I10 -> 0 | D4: ='DATA BASE'!J10 -> 0 | E4: ='DATA BASE'!K10 -> 50 | F4: ='DATA BASE'!L10 -> 57.3 | G4: ='DATA BASE'!M10 -> 21.35 | H4: =G4-D4 -> 21.35
A5: 113M-04 | B5: ='DATA BASE'!H11 -> 90 | C5: ='DATA BASE'!I11 -> 93.6 | D5: ='DATA BASE'!J11 -> 5.76 | E5: ='DATA BASE'!K11 -> 80 | F5: ='DATA BASE'!L11 -> 97.7 | G5: ='DATA BASE'!M11 -> 1.84 | H5: =G5-D5 -> -3.92
A6: 113M-08 BIS | B6: ='DATA BASE'!H12 -> 150 | C6: ='DATA BASE'!I12 -> 73.2 | D6: ='DATA BASE'!J12 -> 40.2 | E6: ='DATA BASE'!K12 -> 130 | F6: ='DATA BASE'!L12 -> 87.2 | G6: ='DATA BASE'!M12 -> 16.64 | H6: =G6-D6 -> -23.56
